Workbook
Name Ust_Autor: USTAWIENIA!$B$8
Name Ust_Jednostka: USTAWIENIA!$B$9
Name Ust_Tolerancja: USTAWIENIA!$B$10
Name Lista_Systemow: LISTY!$A$9:$A$10
Name Lista_AUTOCOLOR: LISTY!$F$9:$F$115
Name Lista_DUXONE: LISTY!$H$9:$H$87
Name ListaAC: LISTY!$F$9:$F$115
Name ListaDX: LISTY!$H$9:$H$87
Name ListaAC_NR: LISTY!$E$9:$E$115
Name ListaDX_NR: LISTY!$G$9:$G$87
Name PigmentyKlucz: PIGMENTY!$A$9:$I$194
Name Meta_Nazwa: START!$C$5
Name Meta_Numer: START!$C$6
Name Meta_Kolor: START!$C$7
Name Meta_Kod: START!$C$8
Name Meta_Producent: START!$C$9
Name Meta_System: START!$C$10
Name Meta_Wersja: START!$C$11
Name Meta_Autor: START!$C$12
Name Meta_Data: START!$C$13
Name Meta_Uwagi: START!$C$14
Name MasaDocelowa: START!$C$15
Name MasaOryg: START!$I$5
Name MasaWlasna: START!$I$6
Name StatusUdzialow: START!$I$11

Sheet START
A1: SYSTEM RECEPTUR LAKIERÓW
A2: AUTOCOLOR + DUXONE | receptura oryginalna → receptura własna → analiza | LibreOffice Calc / Excel
A4: IDENTYFIKACJA RECEPTURY | H4: AKTUALNA RECEPTURA
A5: Nazwa receptury | C5: TEST START — srebrny bazowy | H5: Masa oryginalna (g) | I5: =SUM(RECEPTURA_ORYGINALNA!E12:E51)
A6: Numer receptury | C6: RC-0001 | H6: Masa własna (g) | I6: =SUM(RECEPTURA_WLASNA!F12:F51)
A7: Nazwa koloru | C7: Silver test | H7: Różnica masy (g) | I7: =I6-I5
A8: Kod koloru | C8: TST-001 | H8: Liczba pozycji (własna) | I8: =COUNTIF(RECEPTURA_WLASNA!C12:C51,"<>")
A9: Producent | C9: Warsztat | H9: Suma % oryginał | I9: =IFERROR(SUM(RECEPTURA_ORYGINALNA!G12:G51),0)
A10: System bazowy | C10: AUTOCOLOR | H10: Suma % własna | I10: =IFERROR(SUM(RECEPTURA_WLASNA!J12:J51),0)
A11: Wersja | C11: 1 | H11: Status udziałów | I11: =IF(I8=0,"BRAK DANYCH",IF(ABS(I10-1)<=Ust_Tolerancja/100,"RECEPTURA POPRAWNA","UWAGA — SUMA UDZIAŁÓW = "&TEXT(I10,"0.00%")))
A12: Autor | C12: =Ust_Autor | H12: Duplikaty (własna) | I12: =COUNTIF(RECEPTURA_WLASNA!N12:N51,"DUPLIKAT")
A13: Data | C13: =TODAY() | H13: Brak w bazie | I13: =COUNTIF(RECEPTURA_WLASNA!O12:O51,"BRAK W BAZIE")
A14: Uwagi technologiczne | H14: Dodane / usunięte | I14: =COUNTIF(RECEPTURA_WLASNA!K12:K51,"DODANO")&" / "&COUNTIF(RECEPTURA_WLASNA!K12:K51,"USUNIĘTO")
A15: Masa docelowa (g) | C15: 100 | H15: Zwiększone / zmniejszone | I15: =COUNTIF(RECEPTURA_WLASNA!K12:K51,"ZWIĘKSZONO")&" / "&COUNTIF(RECEPTURA_WLASNA!K12:K51,"ZMNIEJSZONO")
A17: PANEL AKCJI (LibreOffice: Narzędzia → Makra → Zarządzaj makrami → RECEPTURY_LAKIERY.ods)
A18: 1. Nowa receptura | C18: Wyczyść tabele oryginału i własnej, nadaj nowy numer RC, ustaw wersję = 1. Makro: NowaReceptura
A19: 2. Wpisz oryginał | C19: Arkusz RECEPTURA_ORYGINALNA: SYSTEM z listy, potem kliknij NR PIGMENTU — lista z wybranej bazy. Ilość w gramach. Nazwa uzupełni się sama.
A20: 3. Kopia → własna | C20: Makro KopiujDoWlasnej kopiuje skład. Albo przepisz SYSTEM/NR i ilości. ILOŚĆ ORYGINALNA dociąga się kluczem.
A21: 4. Modyfikuj | C21: Zmieniaj złote komórki ilości. Dodawaj pigment z drugiego systemu. Ten sam pigment drugi raz → status DUPLIKAT (zsumuj).
A22: 5. Przelicz masę | C22: Ustaw masę docelową na START. Kolumna ILOŚĆ DO ZWAŻENIA przelicza na żywo. Makro ZastosujPrzeliczenie zapisuje wartości.
A23: 6. Analiza / raport | C23: Otwórz ANALIZA (wykresy) i RAPORT (wydruk). HISTORIA — makro ZapiszWersje nie nadpisuje poprzednich wersji.
A25: NAWIGACJA
A26: Skład oryginalny | C26: Skład roboczy | E26: Wykresy i KPI | G26: Wydruk | I26: Wersje
A27: Wyszukiwarka | C27: Procedury PDF | E27: Baza Autocolor | G27: Baza Duxone | I27: Parametry
A29: Mieszanie systemów: receptura bazowa AUTOCOLOR może zawierać pigmenty DUXONE i odwrotnie. Nie usuwaj wierszy tabel — zeruj ilość (status USUNIĘTO). Komórki złote = wpis, szare = formuła (arkusze bez ochrony — edycja i zapis bez hasła). Źródła nazw: PDF Nexa Autocolor 2K Tint Chart oraz Duxone Tint Descriptions PL; kody z szablonów ODS.

Sheet RECEPTURA_ORYGINALNA
A1: RECEPTURA ORYGINALNA
A2: Skład źródłowy. SYSTEM i NR z listy. Nazwa, jednostka i % liczą się automatycznie.
A3: Nazwa | C3: =Meta_Nazwa | E3: Numer | F3: =Meta_Numer | H3: System bazowy | I3: =Meta_System
A4: Kolor | C4: =Meta_Kolor | E4: Wersja | F4: =Meta_Wersja | H4: Data | I4: =Meta_Data
A5: Masa całkowita (g) | C5: =MasaOryg | E5: Suma % | F5: =IFERROR(SUM(G12:G51),0) | H5: Status | I5: =StatusUdzialow
A7: Najpierw SYSTEM (AUTOCOLOR / DUXONE) z listy, potem kliknij NR PIGMENTU — otworzy się lista z tej bazy. Każdy wiersz ma własny SYSTEM (można mieszać). Po wyborze numeru nazwa i jednostka uzupełnią się same. Ilość ≥ 0. Ten sam klucz dwa razy = DUPLIKAT (zsumuj ilości).
A11: LP | B11: SYSTEM | C11: NR PIGMENTU | D11: NAZWA PIGMENTU | E11: ILOŚĆ | F11: JEDNOSTKA | G11: % UDZIAŁU | H11: UWAGI | I11: KLUCZ | J11: KONTROLA
A12: =IF(C12="","",1) | B12: AUTOCOLOR | C12: P425-900 | D12: =IF(C12="","",IFERROR(VLOOKUP(I12,PigmentyKlucz,4,FALSE),"BRAK W BAZIE")) | E12: 50 | F12: =IF(C12="","",IFERROR(VLOOKUP(I12,PigmentyKlucz,5,FALSE),Ust_Jednostka)) | G12: =IF(OR(C12="",MasaOryg=0),"",E12/MasaOryg) | I12: =IF(C12="","",B12&"|"&IF(ISNUMBER(FIND(" | ",C12)),TRIM(LEFT(C12,FIND(" | ",C12)-1)),C12)) | J12: =IF(C12="","",IF(COUNTIF($I$12:$I$51,I12)>1,"DUPLIKAT",IF(ISERROR(VLOOKUP(I12,PigmentyKlucz,1,FALSE)),"BRAK W BAZIE","OK")))
A13: =IF(C13="","",2) | B13: AUTOCOLOR | C13: P425-984 | D13: =IF(C13="","",IFERROR(VLOOKUP(I13,PigmentyKlucz,4,FALSE),"BRAK W BAZIE")) | E13: 30 | F13: =IF(C13="","",IFERROR(VLOOKUP(I13,PigmentyKlucz,5,FALSE),Ust_Jednostka)) | G13: =IF(OR(C13="",MasaOryg=0),"",E13/MasaOryg) | I13: =IF(C13="","",B13&"|"&IF(ISNUMBER(FIND(" | ",C13)),TRIM(LEFT(C13,FIND(" | ",C13)-1)),C13)) | J13: =IF(C13="","",IF(COUNTIF($I$12:$I$51,I13)>1,"DUPLIKAT",IF(ISERROR(VLOOKUP(I13,PigmentyKlucz,1,FALSE)),"BRAK W BAZIE","OK")))
A14: =IF(C14="","",3) | B14: AUTOCOLOR | C14: P425-948 | D14: =IF(C14="","",IFERROR(VLOOKUP(I14,PigmentyKlucz,4,FALSE),"BRAK W BAZIE")) | E14: 20 | F14: =IF(C14="","",IFERROR(VLOOKUP(I14,PigmentyKlucz,5,FALSE),Ust_Jednostka)) | G14: =IF(OR(C14="",MasaOryg=0),"",E14/MasaOryg) | I14: =IF(C14="","",B14&"|"&IF(ISNUMBER(FIND(" | ",C14)),TRIM(LEFT(C14,FIND(" | ",C14)-1)),C14)) | J14: =IF(C14="","",IF(COUNTIF($I$12:$I$51,I14)>1,"DUPLIKAT",IF(ISERROR(VLOOKUP(I14,PigmentyKlucz,1,FALSE)),"BRAK W BAZIE","OK")))
A15: =IF(C15="","",4) | D15: =IF(C15="","",IFERROR(VLOOKUP(I15,PigmentyKlucz,4,FALSE),"BRAK W BAZIE")) | F15: =IF(C15="","",IFERROR(VLOOKUP(I15,PigmentyKlucz,5,FALSE),Ust_Jednostka)) | G15: =IF(OR(C15="",MasaOryg=0),"",E15/MasaOryg) | I15: =IF(C15="","",B15&"|"&IF(ISNUMBER(FIND(" | ",C15)),TRIM(LEFT(C15,FIND(" | ",C15)-1)),C15)) | J15: =IF(C15="","",IF(COUNTIF($I$12:$I$51,I15)>1,"DUPLIKAT",IF(ISERROR(VLOOKUP(I15,PigmentyKlucz,1,FALSE)),"BRAK W BAZIE","OK")))
A16: =IF(C16="","",5) | D16: =IF(C16="","",IFERROR(VLOOKUP(I16,PigmentyKlucz,4,FALSE),"BRAK W BAZIE")) | F16: =IF(C16="","",IFERROR(VLOOKUP(I16,PigmentyKlucz,5,FALSE),Ust_Jednostka)) | G16: =IF(OR(C16="",MasaOryg=0),"",E16/MasaOryg) | I16: =IF(C16="","",B16&"|"&IF(ISNUMBER(FIND(" | ",C16)),TRIM(LEFT(C16,FIND(" | ",C16)-1)),C16)) | J16: =IF(C16="","",IF(COUNTIF($I$12:$I$51,I16)>1,"DUPLIKAT",IF(ISERROR(VLOOKUP(I16,PigmentyKlucz,1,FALSE)),"BRAK W BAZIE","OK")))
A17: =IF(C17="","",6) | D17: =IF(C17="","",IFERROR(VLOOKUP(I17,PigmentyKlucz,4,FALSE),"BRAK W BAZIE")) | F17: =IF(C17="","",IFERROR(VLOOKUP(I17,PigmentyKlucz,5,FALSE),Ust_Jednostka)) | G17: =IF(OR(C17="",MasaOryg=0),"",E17/MasaOryg) | I17: =IF(C17="","",B17&"|"&IF(ISNUMBER(FIND(" | ",C17)),TRIM(LEFT(C17,FIND(" | ",C17)-1)),C17)) | J17: =IF(C17="","",IF(COUNTIF($I$12:$I$51,I17)>1,"DUPLIKAT",IF(ISERROR(VLOOKUP(I17,PigmentyKlucz,1,FALSE)),"BRAK W BAZIE","OK")))
A18: =IF(C18="","",7) | D18: =IF(C18="","",IFERROR(VLOOKUP(I18,PigmentyKlucz,4,FALSE),"BRAK W BAZIE")) | F18: =IF(C18="","",IFERROR(VLOOKUP(I18,PigmentyKlucz,5,FALSE),Ust_Jednostka)) | G18: =IF(OR(C18="",MasaOryg=0),"",E18/MasaOryg) | I18: =IF(C18="","",B18&"|"&IF(ISNUMBER(FIND(" | ",C18)),TRIM(LEFT(C18,FIND(" | ",C18)-1)),C18)) | J18: =IF(C18="","",IF(COUNTIF($I$12:$I$51,I18)>1,"DUPLIKAT",IF(ISERROR(VLOOKUP(I18,PigmentyKlucz,1,FALSE)),"BRAK W BAZIE","OK")))
A19: =IF(C19="","",8) | D19: =IF(C19="","",IFERROR(VLOOKUP(I19,PigmentyKlucz,4,FALSE),"BRAK W BAZIE")) | F19: =IF(C19="","",IFERROR(VLOOKUP(I19,PigmentyKlucz,5,FALSE),Ust_Jednostka)) | G19: =IF(OR(C19="",MasaOryg=0),"",E19/MasaOryg) | I19: =IF(C19="","",B19&"|"&IF(ISNUMBER(FIND(" | ",C19)),TRIM(LEFT(C19,FIND(" | ",C19)-1)),C19)) | J19: =IF(C19="","",IF(COUNTIF($I$12:$I$51,I19)>1,"DUPLIKAT",IF(ISERROR(VLOOKUP(I19,PigmentyKlucz,1,FALSE)),"BRAK W BAZIE","OK")))
A20: =IF(C20="","",9) | D20: =IF(C20="","",IFERROR(VLOOKUP(I20,PigmentyKlucz,4,FALSE),"BRAK W BAZIE")) | F20: =IF(C20="","",IFERROR(VLOOKUP(I20,PigmentyKlucz,5,FALSE),Ust_Jednostka)) | G20: =IF(OR(C20="",MasaOryg=0),"",E20/MasaOryg) | I20: =IF(C20="","",B20&"|"&IF(ISNUMBER(FIND(" | ",C20)),TRIM(LEFT(C20,FIND(" | ",C20)-1)),C20)) | J20: =IF(C20="","",IF(COUNTIF($I$12:$I$51,I20)>1,"DUPLIKAT",IF(ISERROR(VLOOKUP(I20,PigmentyKlucz,1,FALSE)),"BRAK W BAZIE","OK")))
A21: =IF(C21="","",10) | D21: =IF(C21="","",IFERROR(VLOOKUP(I21,PigmentyKlucz,4,FALSE),"BRAK W BAZIE")) | F21: =IF(C21="","",IFERROR(VLOOKUP(I21,PigmentyKlucz,5,FALSE),Ust_Jednostka)) | G21: =IF(OR(C21="",MasaOryg=0),"",E21/MasaOryg) | I21: =IF(C21="","",B21&"|"&IF(ISNUMBER(FIND(" | ",C21)),TRIM(LEFT(C21,FIND(" | ",C21)-1)),C21)) | J21: =IF(C21="","",IF(COUNTIF($I$12:$I$51,I21)>1,"DUPLIKAT",IF(ISERROR(VLOOKUP(I21,PigmentyKlucz,1,FALSE)),"BRAK W BAZIE","OK")))
A22: =IF(C22="","",11) | D22: =IF(C22="","",IFERROR(VLOOKUP(I22,PigmentyKlucz,4,FALSE),"BRAK W BAZIE")) | F22: =IF(C22="","",IFERROR(VLOOKUP(I22,PigmentyKlucz,5,FALSE),Ust_Jednostka)) | G22: =IF(OR(C22="",MasaOryg=0),"",E22/MasaOryg) | I22: =IF(C22="","",B22&"|"&IF(ISNUMBER(FIND(" | ",C22)),TRIM(LEFT(C22,FIND(" | ",C22)-1)),C22)) | J22: =IF(C22="","",IF(COUNTIF($I$12:$I$51,I22)>1,"DUPLIKAT",IF(ISERROR(VLOOKUP(I22,PigmentyKlucz,1,FALSE)),"BRAK W BAZIE","OK")))
A23: =IF(C23="","",12) | D23: =IF(C23="","",IFERROR(VLOOKUP(I23,PigmentyKlucz,4,FALSE),"BRAK W BAZIE")) | F23: =IF(C23="","",IFERROR(VLOOKUP(I23,PigmentyKlucz,5,FALSE),Ust_Jednostka)) | G23: =IF(OR(C23="",MasaOryg=0),"",E23/MasaOryg) | I23: =IF(C23="","",B23&"|"&IF(ISNUMBER(FIND(" | ",C23)),TRIM(LEFT(C23,FIND(" | ",C23)-1)),C23)) | J23: =IF(C23="","",IF(COUNTIF($I$12:$I$51,I23)>1,"DUPLIKAT",IF(ISERROR(VLOOKUP(I23,PigmentyKlucz,1,FALSE)),"BRAK W BAZIE","OK")))
A24: =IF(C24="","",13) | D24: =IF(C24="","",IFERROR(VLOOKUP(I24,PigmentyKlucz,4,FALSE),"BRAK W BAZIE")) | F24: =IF(C24="","",IFERROR(VLOOKUP(I24,PigmentyKlucz,5,FALSE),Ust_Jednostka)) | G24: =IF(OR(C24="",MasaOryg=0),"",E24/MasaOryg) | I24: =IF(C24="","",B24&"|"&IF(ISNUMBER(FIND(" | ",C24)),TRIM(LEFT(C24,FIND(" | ",C24)-1)),C24)) | J24: =IF(C24="","",IF(COUNTIF($I$12:$I$51,I24)>1,"DUPLIKAT",IF(ISERROR(VLOOKUP(I24,PigmentyKlucz,1,FALSE)),"BRAK W BAZIE","OK")))
A25: =IF(C25="","",14) | D25: =IF(C25="","",IFERROR(VLOOKUP(I25,PigmentyKlucz,4,FALSE),"BRAK W BAZIE")) | F25: =IF(C25="","",IFERROR(VLOOKUP(I25,PigmentyKlucz,5,FALSE),Ust_Jednostka)) | G25: =IF(OR(C25="",MasaOryg=0),"",E25/MasaOryg) | I25: =IF(C25="","",B25&"|"&IF(ISNUMBER(FIND(" | ",C25)),TRIM(LEFT(C25,FIND(" | ",C25)-1)),C25)) | J25: =IF(C25="","",IF(COUNTIF($I$12:$I$51,I25)>1,"DUPLIKAT",IF(ISERROR(VLOOKUP(I25,PigmentyKlucz,1,FALSE)),"BRAK W BAZIE","OK")))
A26: =IF(C26="","",15) | D26: =IF(C26="","",IFERROR(VLOOKUP(I26,PigmentyKlucz,4,FALSE),"BRAK W BAZIE")) | F26: =IF(C26="","",IFERROR(VLOOKUP(I26,PigmentyKlucz,5,FALSE),Ust_Jednostka)) | G26: =IF(OR(C26="",MasaOryg=0),"",E26/MasaOryg) | I26: =IF(C26="","",B26&"|"&IF(ISNUMBER(FIND(" | ",C26)),TRIM(LEFT(C26,FIND(" | ",C26)-1)),C26)) | J26: =IF(C26="","",IF(COUNTIF($I$12:$I$51,I26)>1,"DUPLIKAT",IF(ISERROR(VLOOKUP(I26,PigmentyKlucz,1,FALSE)),"BRAK W BAZIE","OK")))
A27: =IF(C27="","",16) | D27: =IF(C27="","",IFERROR(VLOOKUP(I27,PigmentyKlucz,4,FALSE),"BRAK W BAZIE")) | F27: =IF(C27="","",IFERROR(VLOOKUP(I27,PigmentyKlucz,5,FALSE),Ust_Jednostka)) | G27: =IF(OR(C27="",MasaOryg=0),"",E27/MasaOryg) | I27: =IF(C27="","",B27&"|"&IF(ISNUMBER(FIND(" | ",C27)),TRIM(LEFT(C27,FIND(" | ",C27)-1)),C27)) | J27: =IF(C27="","",IF(COUNTIF($I$12:$I$51,I27)>1,"DUPLIKAT",IF(ISERROR(VLOOKUP(I27,PigmentyKlucz,1,FALSE)),"BRAK W BAZIE","OK")))
A28: =IF(C28="","",17) | D28: =IF(C28="","",IFERROR(VLOOKUP(I28,PigmentyKlucz,4,FALSE),"BRAK W BAZIE")) | F28: =IF(C28="","",IFERROR(VLOOKUP(I28,PigmentyKlucz,5,FALSE),Ust_Jednostka)) | G28: =IF(OR(C28="",MasaOryg=0),"",E28/MasaOryg) | I28: =IF(C28="","",B28&"|"&IF(ISNUMBER(FIND(" | ",C28)),TRIM(LEFT(C28,FIND(" | ",C28)-1)),C28)) | J28: =IF(C28="","",IF(COUNTIF($I$12:$I$51,I28)>1,"DUPLIKAT",IF(ISERROR(VLOOKUP(I28,PigmentyKlucz,1,FALSE)),"BRAK W BAZIE","OK")))
A29: =IF(C29="","",18) | D29: =IF(C29="","",IFERROR(VLOOKUP(I29,PigmentyKlucz,4,FALSE),"BRAK W BAZIE")) | F29: =IF(C29="","",IFERROR(VLOOKUP(I29,PigmentyKlucz,5,FALSE),Ust_Jednostka)) | G29: =IF(OR(C29="",MasaOryg=0),"",E29/MasaOryg) | I29: =IF(C29="","",B29&"|"&IF(ISNUMBER(FIND(" | ",C29)),TRIM(LEFT(C29,FIND(" | ",C29)-1)),C29)) | J29: =IF(C29="","",IF(COUNTIF($I$12:$I$51,I29)>1,"DUPLIKAT",IF(ISERROR(VLOOKUP(I29,PigmentyKlucz,1,FALSE)),"BRAK W BAZIE","OK")))
A30: =IF(C30="","",19) | D30: =IF(C30="","",IFERROR(VLOOKUP(I30,PigmentyKlucz,4,FALSE),"BRAK W BAZIE")) | F30: =IF(C30="","",IFERROR(VLOOKUP(I30,PigmentyKlucz,5,FALSE),Ust_Jednostka)) | G30: =IF(OR(C30="",MasaOryg=0),"",E30/MasaOryg) | I30: =IF(C30="","",B30&"|"&IF(ISNUMBER(FIND(" | ",C30)),TRIM(LEFT(C30,FIND(" | ",C30)-1)),C30)) | J30: =IF(C30="","",IF(COUNTIF($I$12:$I$51,I30)>1,"DUPLIKAT",IF(ISERROR(VLOOKUP(I30,PigmentyKlucz,1,FALSE)),"BRAK W BAZIE","OK")))
A31: =IF(C31="","",20) | D31: =IF(C31="","",IFERROR(VLOOKUP(I31,PigmentyKlucz,4,FALSE),"BRAK W BAZIE")) | F31: =IF(C31="","",IFERROR(VLOOKUP(I31,PigmentyKlucz,5,FALSE),Ust_Jednostka)) | G31: =IF(OR(C31="",MasaOryg=0),"",E31/MasaOryg) | I31: =IF(C31="","",B31&"|"&IF(ISNUMBER(FIND(" | ",C31)),TRIM(LEFT(C31,FIND(" | ",C31)-1)),C31)) | J31: =IF(C31="","",IF(COUNTIF($I$12:$I$51,I31)>1,"DUPLIKAT",IF(ISERROR(VLOOKUP(I31,PigmentyKlucz,1,FALSE)),"BRAK W BAZIE","OK")))
A32: =IF(C32="","",21) | D32: =IF(C32="","",IFERROR(VLOOKUP(I32,PigmentyKlucz,4,FALSE),"BRAK W BAZIE")) | F32: =IF(C32="","",IFERROR(VLOOKUP(I32,PigmentyKlucz,5,FALSE),Ust_Jednostka)) | G32: =IF(OR(C32="",MasaOryg=0),"",E32/MasaOryg) | I32: =IF(C32="","",B32&"|"&IF(ISNUMBER(FIND(" | ",C32)),TRIM(LEFT(C32,FIND(" | ",C32)-1)),C32)) | J32: =IF(C32="","",IF(COUNTIF($I$12:$I$51,I32)>1,"DUPLIKAT",IF(ISERROR(VLOOKUP(I32,PigmentyKlucz,1,FALSE)),"BRAK W BAZIE","OK")))
A33: =IF(C33="","",22) | D33: =IF(C33="","",IFERROR(VLOOKUP(I33,PigmentyKlucz,4,FALSE),"BRAK W BAZIE")) | F33: =IF(C33="","",IFERROR(VLOOKUP(I33,PigmentyKlucz,5,FALSE),Ust_Jednostka)) | G33: =IF(OR(C33="",MasaOryg=0),"",E33/MasaOryg) | I33: =IF(C33="","",B33&"|"&IF(ISNUMBER(FIND(" | ",C33)),TRIM(LEFT(C33,FIND(" | ",C33)-1)),C33)) | J33: =IF(C33="","",IF(COUNTIF($I$12:$I$51,I33)>1,"DUPLIKAT",IF(ISERROR(VLOOKUP(I33,PigmentyKlucz,1,FALSE)),"BRAK W BAZIE","OK")))
A34: =IF(C34="","",23) | D34: =IF(C34="","",IFERROR(VLOOKUP(I34,PigmentyKlucz,4,FALSE),"BRAK W BAZIE")) | F34: =IF(C34="","",IFERROR(VLOOKUP(I34,PigmentyKlucz,5,FALSE),Ust_Jednostka)) | G34: =IF(OR(C34="",MasaOryg=0),"",E34/MasaOryg) | I34: =IF(C34="","",B34&"|"&IF(ISNUMBER(FIND(" | ",C34)),TRIM(LEFT(C34,FIND(" | ",C34)-1)),C34)) | J34: =IF(C34="","",IF(COUNTIF($I$12:$I$51,I34)>1,"DUPLIKAT",IF(ISERROR(VLOOKUP(I34,PigmentyKlucz,1,FALSE)),"BRAK W BAZIE","OK")))
A35: =IF(C35="","",24) | D35: =IF(C35="","",IFERROR(VLOOKUP(I35,PigmentyKlucz,4,FALSE),"BRAK W BAZIE")) | F35: =IF(C35="","",IFERROR(VLOOKUP(I35,PigmentyKlucz,5,FALSE),Ust_Jednostka)) | G35: =IF(OR(C35="",MasaOryg=0),"",E35/MasaOryg) | I35: =IF(C35="","",B35&"|"&IF(ISNUMBER(FIND(" | ",C35)),TRIM(LEFT(C35,FIND(" | ",C35)-1)),C35)) | J35: =IF(C35="","",IF(COUNTIF($I$12:$I$51,I35)>1,"DUPLIKAT",IF(ISERROR(VLOOKUP(I35,PigmentyKlucz,1,FALSE)),"BRAK W BAZIE","OK")))
A36: =IF(C36="","",25) | D36: =IF(C36="","",IFERROR(VLOOKUP(I36,PigmentyKlucz,4,FALSE),"BRAK W BAZIE")) | F36: =IF(C36="","",IFERROR(VLOOKUP(I36,PigmentyKlucz,5,FALSE),Ust_Jednostka)) | G36: =IF(OR(C36="",MasaOryg=0),"",E36/MasaOryg) | I36: =IF(C36="","",B36&"|"&IF(ISNUMBER(FIND(" | ",C36)),TRIM(LEFT(C36,FIND(" | ",C36)-1)),C36)) | J36: =IF(C36="","",IF(COUNTIF($I$12:$I$51,I36)>1,"DUPLIKAT",IF(ISERROR(VLOOKUP(I36,PigmentyKlucz,1,FALSE)),"BRAK W BAZIE","OK")))
A37: =IF(C37="","",26) | D37: =IF(C37="","",IFERROR(VLOOKUP(I37,PigmentyKlucz,4,FALSE),"BRAK W BAZIE")) | F37: =IF(C37="","",IFERROR(VLOOKUP(I37,PigmentyKlucz,5,FALSE),Ust_Jednostka)) | G37: =IF(OR(C37="",MasaOryg=0),"",E37/MasaOryg) | I37: =IF(C37="","",B37&"|"&IF(ISNUMBER(FIND(" | ",C37)),TRIM(LEFT(C37,FIND(" | ",C37)-1)),C37)) | J37: =IF(C37="","",IF(COUNTIF($I$12:$I$51,I37)>1,"DUPLIKAT",IF(ISERROR(VLOOKUP(I37,PigmentyKlucz,1,FALSE)),"BRAK W BAZIE","OK")))
A38: =IF(C38="","",27) | D38: =IF(C38="","",IFERROR(VLOOKUP(I38,PigmentyKlucz,4,FALSE),"BRAK W BAZIE")) | F38: =IF(C38="","",IFERROR(VLOOKUP(I38,PigmentyKlucz,5,FALSE),Ust_Jednostka)) | G38: =IF(OR(C38="",MasaOryg=0),"",E38/MasaOryg) | I38: =IF(C38="","",B38&"|"&IF(ISNUMBER(FIND(" | ",C38)),TRIM(LEFT(C38,FIND(" | ",C38)-1)),C38)) | J38: =IF(C38="","",IF(COUNTIF($I$12:$I$51,I38)>1,"DUPLIKAT",IF(ISERROR(VLOOKUP(I38,PigmentyKlucz,1,FALSE)),"BRAK W BAZIE","OK")))
A39: =IF(C39="","",28) | D39: =IF(C39="","",IFERROR(VLOOKUP(I39,PigmentyKlucz,4,FALSE),"BRAK W BAZIE")) | F39: =IF(C39="","",IFERROR(VLOOKUP(I39,PigmentyKlucz,5,FALSE),Ust_Jednostka)) | G39: =IF(OR(C39="",MasaOryg=0),"",E39/MasaOryg) | I39: =IF(C39="","",B39&"|"&IF(ISNUMBER(FIND(" | ",C39)),TRIM(LEFT(C39,FIND(" | ",C39)-1)),C39)) | J39: =IF(C39="","",IF(COUNTIF($I$12:$I$51,I39)>1,"DUPLIKAT",IF(ISERROR(VLOOKUP(I39,PigmentyKlucz,1,FALSE)),"BRAK W BAZIE","OK")))
A40: =IF(C40="","",29) | D40: =IF(C40="","",IFERROR(VLOOKUP(I40,PigmentyKlucz,4,FALSE),"BRAK W BAZIE")) | F40: =IF(C40="","",IFERROR(VLOOKUP(I40,PigmentyKlucz,5,FALSE),Ust_Jednostka)) | G40: =IF(OR(C40="",MasaOryg=0),"",E40/MasaOryg) | I40: =IF(C40="","",B40&"|"&IF(ISNUMBER(FIND(" | ",C40)),TRIM(LEFT(C40,FIND(" | ",C40)-1)),C40)) | J40: =IF(C40="","",IF(COUNTIF($I$12:$I$51,I40)>1,"DUPLIKAT",IF(ISERROR(VLOOKUP(I40,PigmentyKlucz,1,FALSE)),"BRAK W BAZIE","OK")))
A41: =IF(C41="","",30) | D41: =IF(C41="","",IFERROR(VLOOKUP(I41,PigmentyKlucz,4,FALSE),"BRAK W BAZIE")) | F41: =IF(C41="","",IFERROR(VLOOKUP(I41,PigmentyKlucz,5,FALSE),Ust_Jednostka)) | G41: =IF(OR(C41="",MasaOryg=0),"",E41/MasaOryg) | I41: =IF(C41="","",B41&"|"&IF(ISNUMBER(FIND(" | ",C41)),TRIM(LEFT(C41,FIND(" | ",C41)-1)),C41)) | J41: =IF(C41="","",IF(COUNTIF($I$12:$I$51,I41)>1,"DUPLIKAT",IF(ISERROR(VLOOKUP(I41,PigmentyKlucz,1,FALSE)),"BRAK W BAZIE","OK")))
A42: =IF(C42="","",31) | D42: =IF(C42="","",IFERROR(VLOOKUP(I42,PigmentyKlucz,4,FALSE),"BRAK W BAZIE")) | F42: =IF(C42="","",IFERROR(VLOOKUP(I42,PigmentyKlucz,5,FALSE),Ust_Jednostka)) | G42: =IF(OR(C42="",MasaOryg=0),"",E42/MasaOryg) | I42: =IF(C42="","",B42&"|"&IF(ISNUMBER(FIND(" | ",C42)),TRIM(LEFT(C42,FIND(" | ",C42)-1)),C42)) | J42: =IF(C42="","",IF(COUNTIF($I$12:$I$51,I42)>1,"DUPLIKAT",IF(ISERROR(VLOOKUP(I42,PigmentyKlucz,1,FALSE)),"BRAK W BAZIE","OK")))
A43: =IF(C43="","",32) | D43: =IF(C43="","",IFERROR(VLOOKUP(I43,PigmentyKlucz,4,FALSE),"BRAK W BAZIE")) | F43: =IF(C43="","",IFERROR(VLOOKUP(I43,PigmentyKlucz,5,FALSE),Ust_Jednostka)) | G43: =IF(OR(C43="",MasaOryg=0),"",E43/MasaOryg) | I43: =IF(C43="","",B43&"|"&IF(ISNUMBER(FIND(" | ",C43)),TRIM(LEFT(C43,FIND(" | ",C43)-1)),C43)) | J43: =IF(C43="","",IF(COUNTIF($I$12:$I$51,I43)>1,"DUPLIKAT",IF(ISERROR(VLOOKUP(I43,PigmentyKlucz,1,FALSE)),"BRAK W BAZIE","OK")))
A44: =IF(C44="","",33) | D44: =IF(C44="","",IFERROR(VLOOKUP(I44,PigmentyKlucz,4,FALSE),"BRAK W BAZIE")) | F44: =IF(C44="","",IFERROR(VLOOKUP(I44,PigmentyKlucz,5,FALSE),Ust_Jednostka)) | G44: =IF(OR(C44="",MasaOryg=0),"",E44/MasaOryg) | I44: =IF(C44="","",B44&"|"&IF(ISNUMBER(FIND(" | ",C44)),TRIM(LEFT(C44,FIND(" | ",C44)-1)),C44)) | J44: =IF(C44="","",IF(COUNTIF($I$12:$I$51,I44)>1,"DUPLIKAT",IF(ISERROR(VLOOKUP(I44,PigmentyKlucz,1,FALSE)),"BRAK W BAZIE","OK")))
...

Sheet RECEPTURA_WLASNA
A1: RECEPTURA WŁASNA
A2: Główny arkusz roboczy. ILOŚĆ ORYGINALNA dociągana kluczem SYSTEM|NR. Można dodać pigment z drugiego systemu.
A3: Nazwa | C3: =Meta_Nazwa | E3: Numer | F3: =Meta_Numer | H3: System bazowy | I3: =Meta_System | K3: Masa docelowa (g) | M3: =MasaDocelowa
A4: Kolor | C4: =Meta_Kolor | E4: Wersja | F4: =Meta_Wersja | H4: Data | I4: =Meta_Data | K4: Masa własna (g) | M4: =MasaWlasna
A5: Status udziałów | C5: =StatusUdzialow | E5: Masa oryg. (g) | F5: =MasaOryg | H5: Różnica (g) | I5: =MasaWlasna-MasaOryg | K5: Wsp. skali | M5: =IFERROR(MasaDocelowa/MasaWlasna,0)
A7: Kolumny złote: SYSTEM, NR, ILOŚĆ WŁASNA, UWAGI. Kliknij NR PIGMENTU — lista z bazy SYSTEM w tym wierszu (można mieszać AUTOCOLOR i DUXONE). ILOŚĆ DO ZWAŻENIA = ilość własna × masa docelowa / masa własna (przeliczenie na 100 g / 500 g / 1 kg / dowolna). STATUS: BEZ ZMIAN / ZWIĘKSZONO / ZMNIEJSZONO / DODANO / USUNIĘTO. Usunięcie = ilość własna 0 przy ilości oryginalnej > 0.
A11: LP | B11: SYSTEM | C11: NR PIGMENTU | D11: NAZWA PIGMENTU | E11: ILOŚĆ ORYGINALNA | F11: ILOŚĆ WŁASNA | G11: RÓŻNICA | H11: ZMIANA % | I11: % W RECEPTURZE ORYGINALNEJ | J11: % W RECEPTURZE WŁASNEJ | K11: STATUS | L11: UWAGI | M11: ILOŚĆ DO ZWAŻENIA | N11: KONTROLA | O11: WALIDACJA BAZY | P11: KLUCZ
A12: =IF(C12="","",1) | B12: AUTOCOLOR | C12: P425-900 | D12: =IF(C12="","",IFERROR(VLOOKUP(P12,PigmentyKlucz,4,FALSE),"BRAK W BAZIE")) | E12: =IF(C12="","",IFERROR(SUMIF(RECEPTURA_ORYGINALNA!$I$12:$I$51,P12,RECEPTURA_ORYGINALNA!$E$12:$E$51),0)) | F12: 50 | G12: =IF(C12="","",N(F12)-N(E12)) | H12: =IF(C12="","",IF(N(E12)=0,IF(N(F12)>0,"",0),IFERROR((N(F12)-N(E12))/N(E12),0))) | I12: =IF(C12="","",IF(MasaOryg=0,"",N(E12)/MasaOryg)) | J12: =IF(C12="","",IF(MasaWlasna=0,"",N(F12)/MasaWlasna)) | K12: =IF(C12="","",IF(AND(N(E12)>0,N(F12)=0),"USUNIĘTO",IF(AND(N(E12)=0,N(F12)>0),"DODANO",IF(N(F12)>N(E12),"ZWIĘKSZONO",IF(N(F12)<N(E12),"ZMNIEJSZONO","BEZ ZMIAN"))))) | M12: =IF(C12="","",IFERROR(N(F12)*MasaDocelowa/MasaWlasna,0)) | N12: =IF(C12="","",IF(COUNTIF($P$12:$P$51,P12)>1,"DUPLIKAT","OK")) | O12: =IF(C12="","",IF(B12="","BRAK SYSTEMU",IF(ISERROR(VLOOKUP(P12,PigmentyKlucz,1,FALSE)),"BRAK W BAZIE","OK"))) | P12: =IF(C12="","",B12&"|"&IF(ISNUMBER(FIND(" | ",C12)),TRIM(LEFT(C12,FIND(" | ",C12)-1)),C12))
A13: =IF(C13="","",2) | B13: AUTOCOLOR | C13: P425-984 | D13: =IF(C13="","",IFERROR(VLOOKUP(P13,PigmentyKlucz,4,FALSE),"BRAK W BAZIE")) | E13: =IF(C13="","",IFERROR(SUMIF(RECEPTURA_ORYGINALNA!$I$12:$I$51,P13,RECEPTURA_ORYGINALNA!$E$12:$E$51),0)) | F13: 30 | G13: =IF(C13="","",N(F13)-N(E13)) | H13: =IF(C13="","",IF(N(E13)=0,IF(N(F13)>0,"",0),IFERROR((N(F13)-N(E13))/N(E13),0))) | I13: =IF(C13="","",IF(MasaOryg=0,"",N(E13)/MasaOryg)) | J13: =IF(C13="","",IF(MasaWlasna=0,"",N(F13)/MasaWlasna)) | K13: =IF(C13="","",IF(AND(N(E13)>0,N(F13)=0),"USUNIĘTO",IF(AND(N(E13)=0,N(F13)>0),"DODANO",IF(N(F13)>N(E13),"ZWIĘKSZONO",IF(N(F13)<N(E13),"ZMNIEJSZONO","BEZ ZMIAN"))))) | M13: =IF(C13="","",IFERROR(N(F13)*MasaDocelowa/MasaWlasna,0)) | N13: =IF(C13="","",IF(COUNTIF($P$12:$P$51,P13)>1,"DUPLIKAT","OK")) | O13: =IF(C13="","",IF(B13="","BRAK SYSTEMU",IF(ISERROR(VLOOKUP(P13,PigmentyKlucz,1,FALSE)),"BRAK W BAZIE","OK"))) | P13: =IF(C13="","",B13&"|"&IF(ISNUMBER(FIND(" | ",C13)),TRIM(LEFT(C13,FIND(" | ",C13)-1)),C13))
A14: =IF(C14="","",3) | B14: AUTOCOLOR | C14: P425-948 | D14: =IF(C14="","",IFERROR(VLOOKUP(P14,PigmentyKlucz,4,FALSE),"BRAK W BAZIE")) | E14: =IF(C14="","",IFERROR(SUMIF(RECEPTURA_ORYGINALNA!$I$12:$I$51,P14,RECEPTURA_ORYGINALNA!$E$12:$E$51),0)) | F14: 20 | G14: =IF(C14="","",N(F14)-N(E14)) | H14: =IF(C14="","",IF(N(E14)=0,IF(N(F14)>0,"",0),IFERROR((N(F14)-N(E14))/N(E14),0))) | I14: =IF(C14="","",IF(MasaOryg=0,"",N(E14)/MasaOryg)) | J14: =IF(C14="","",IF(MasaWlasna=0,"",N(F14)/MasaWlasna)) | K14: =IF(C14="","",IF(AND(N(E14)>0,N(F14)=0),"USUNIĘTO",IF(AND(N(E14)=0,N(F14)>0),"DODANO",IF(N(F14)>N(E14),"ZWIĘKSZONO",IF(N(F14)<N(E14),"ZMNIEJSZONO","BEZ ZMIAN"))))) | M14: =IF(C14="","",IFERROR(N(F14)*MasaDocelowa/MasaWlasna,0)) | N14: =IF(C14="","",IF(COUNTIF($P$12:$P$51,P14)>1,"DUPLIKAT","OK")) | O14: =IF(C14="","",IF(B14="","BRAK SYSTEMU",IF(ISERROR(VLOOKUP(P14,PigmentyKlucz,1,FALSE)),"BRAK W BAZIE","OK"))) | P14: =IF(C14="","",B14&"|"&IF(ISNUMBER(FIND(" | ",C14)),TRIM(LEFT(C14,FIND(" | ",C14)-1)),C14))
A15: =IF(C15="","",4) | D15: =IF(C15="","",IFERROR(VLOOKUP(P15,PigmentyKlucz,4,FALSE),"BRAK W BAZIE")) | E15: =IF(C15="","",IFERROR(SUMIF(RECEPTURA_ORYGINALNA!$I$12:$I$51,P15,RECEPTURA_ORYGINALNA!$E$12:$E$51),0)) | G15: =IF(C15="","",N(F15)-N(E15)) | H15: =IF(C15="","",IF(N(E15)=0,IF(N(F15)>0,"",0),IFERROR((N(F15)-N(E15))/N(E15),0))) | I15: =IF(C15="","",IF(MasaOryg=0,"",N(E15)/MasaOryg)) | J15: =IF(C15="","",IF(MasaWlasna=0,"",N(F15)/MasaWlasna)) | K15: =IF(C15="","",IF(AND(N(E15)>0,N(F15)=0),"USUNIĘTO",IF(AND(N(E15)=0,N(F15)>0),"DODANO",IF(N(F15)>N(E15),"ZWIĘKSZONO",IF(N(F15)<N(E15),"ZMNIEJSZONO","BEZ ZMIAN"))))) | M15: =IF(C15="","",IFERROR(N(F15)*MasaDocelowa/MasaWlasna,0)) | N15: =IF(C15="","",IF(COUNTIF($P$12:$P$51,P15)>1,"DUPLIKAT","OK")) | O15: =IF(C15="","",IF(B15="","BRAK SYSTEMU",IF(ISERROR(VLOOKUP(P15,PigmentyKlucz,1,FALSE)),"BRAK W BAZIE","OK"))) | P15: =IF(C15="","",B15&"|"&IF(ISNUMBER(FIND(" | ",C15)),TRIM(LEFT(C15,FIND(" | ",C15)-1)),C15))
A16: =IF(C16="","",5) | D16: =IF(C16="","",IFERROR(VLOOKUP(P16,PigmentyKlucz,4,FALSE),"BRAK W BAZIE")) | E16: =IF(C16="","",IFERROR(SUMIF(RECEPTURA_ORYGINALNA!$I$12:$I$51,P16,RECEPTURA_ORYGINALNA!$E$12:$E$51),0)) | G16: =IF(C16="","",N(F16)-N(E16)) | H16: =IF(C16="","",IF(N(E16)=0,IF(N(F16)>0,"",0),IFERROR((N(F16)-N(E16))/N(E16),0))) | I16: =IF(C16="","",IF(MasaOryg=0,"",N(E16)/MasaOryg)) | J16: =IF(C16="","",IF(MasaWlasna=0,"",N(F16)/MasaWlasna)) | K16: =IF(C16="","",IF(AND(N(E16)>0,N(F16)=0),"USUNIĘTO",IF(AND(N(E16)=0,N(F16)>0),"DODANO",IF(N(F16)>N(E16),"ZWIĘKSZONO",IF(N(F16)<N(E16),"ZMNIEJSZONO","BEZ ZMIAN"))))) | M16: =IF(C16="","",IFERROR(N(F16)*MasaDocelowa/MasaWlasna,0)) | N16: =IF(C16="","",IF(COUNTIF($P$12:$P$51,P16)>1,"DUPLIKAT","OK")) | O16: =IF(C16="","",IF(B16="","BRAK SYSTEMU",IF(ISERROR(VLOOKUP(P16,PigmentyKlucz,1,FALSE)),"BRAK W BAZIE","OK"))) | P16: =IF(C16="","",B16&"|"&IF(ISNUMBER(FIND(" | ",C16)),TRIM(LEFT(C16,FIND(" | ",C16)-1)),C16))
A17: =IF(C17="","",6) | D17: =IF(C17="","",IFERROR(VLOOKUP(P17,PigmentyKlucz,4,FALSE),"BRAK W BAZIE")) | E17: =IF(C17="","",IFERROR(SUMIF(RECEPTURA_ORYGINALNA!$I$12:$I$51,P17,RECEPTURA_ORYGINALNA!$E$12:$E$51),0)) | G17: =IF(C17="","",N(F17)-N(E17)) | H17: =IF(C17="","",IF(N(E17)=0,IF(N(F17)>0,"",0),IFERROR((N(F17)-N(E17))/N(E17),0))) | I17: =IF(C17="","",IF(MasaOryg=0,"",N(E17)/MasaOryg)) | J17: =IF(C17="","",IF(MasaWlasna=0,"",N(F17)/MasaWlasna)) | K17: =IF(C17="","",IF(AND(N(E17)>0,N(F17)=0),"USUNIĘTO",IF(AND(N(E17)=0,N(F17)>0),"DODANO",IF(N(F17)>N(E17),"ZWIĘKSZONO",IF(N(F17)<N(E17),"ZMNIEJSZONO","BEZ ZMIAN"))))) | M17: =IF(C17="","",IFERROR(N(F17)*MasaDocelowa/MasaWlasna,0)) | N17: =IF(C17="","",IF(COUNTIF($P$12:$P$51,P17)>1,"DUPLIKAT","OK")) | O17: =IF(C17="","",IF(B17="","BRAK SYSTEMU",IF(ISERROR(VLOOKUP(P17,PigmentyKlucz,1,FALSE)),"BRAK W BAZIE","OK"))) | P17: =IF(C17="","",B17&"|"&IF(ISNUMBER(FIND(" | ",C17)),TRIM(LEFT(C17,FIND(" | ",C17)-1)),C17))
A18: =IF(C18="","",7) | D18: =IF(C18="","",IFERROR(VLOOKUP(P18,PigmentyKlucz,4,FALSE),"BRAK W BAZIE")) | E18: =IF(C18="","",IFERROR(SUMIF(RECEPTURA_ORYGINALNA!$I$12:$I$51,P18,RECEPTURA_ORYGINALNA!$E$12:$E$51),0)) | G18: =IF(C18="","",N(F18)-N(E18)) | H18: =IF(C18="","",IF(N(E18)=0,IF(N(F18)>0,"",0),IFERROR((N(F18)-N(E18))/N(E18),0))) | I18: =IF(C18="","",IF(MasaOryg=0,"",N(E18)/MasaOryg)) | J18: =IF(C18="","",IF(MasaWlasna=0,"",N(F18)/MasaWlasna)) | K18: =IF(C18="","",IF(AND(N(E18)>0,N(F18)=0),"USUNIĘTO",IF(AND(N(E18)=0,N(F18)>0),"DODANO",IF(N(F18)>N(E18),"ZWIĘKSZONO",IF(N(F18)<N(E18),"ZMNIEJSZONO","BEZ ZMIAN"))))) | M18: =IF(C18="","",IFERROR(N(F18)*MasaDocelowa/MasaWlasna,0)) | N18: =IF(C18="","",IF(COUNTIF($P$12:$P$51,P18)>1,"DUPLIKAT","OK")) | O18: =IF(C18="","",IF(B18="","BRAK SYSTEMU",IF(ISERROR(VLOOKUP(P18,PigmentyKlucz,1,FALSE)),"BRAK W BAZIE","OK"))) | P18: =IF(C18="","",B18&"|"&IF(ISNUMBER(FIND(" | ",C18)),TRIM(LEFT(C18,FIND(" | ",C18)-1)),C18))
A19: =IF(C19="","",8) | D19: =IF(C19="","",IFERROR(VLOOKUP(P19,PigmentyKlucz,4,FALSE),"BRAK W BAZIE")) | E19: =IF(C19="","",IFERROR(SUMIF(RECEPTURA_ORYGINALNA!$I$12:$I$51,P19,RECEPTURA_ORYGINALNA!$E$12:$E$51),0)) | G19: =IF(C19="","",N(F19)-N(E19)) | H19: =IF(C19="","",IF(N(E19)=0,IF(N(F19)>0,"",0),IFERROR((N(F19)-N(E19))/N(E19),0))) | I19: =IF(C19="","",IF(MasaOryg=0,"",N(E19)/MasaOryg)) | J19: =IF(C19="","",IF(MasaWlasna=0,"",N(F19)/MasaWlasna)) | K19: =IF(C19="","",IF(AND(N(E19)>0,N(F19)=0),"USUNIĘTO",IF(AND(N(E19)=0,N(F19)>0),"DODANO",IF(N(F19)>N(E19),"ZWIĘKSZONO",IF(N(F19)<N(E19),"ZMNIEJSZONO","BEZ ZMIAN"))))) | M19: =IF(C19="","",IFERROR(N(F19)*MasaDocelowa/MasaWlasna,0)) | N19: =IF(C19="","",IF(COUNTIF($P$12:$P$51,P19)>1,"DUPLIKAT","OK")) | O19: =IF(C19="","",IF(B19="","BRAK SYSTEMU",IF(ISERROR(VLOOKUP(P19,PigmentyKlucz,1,FALSE)),"BRAK W BAZIE","OK"))) | P19: =IF(C19="","",B19&"|"&IF(ISNUMBER(FIND(" | ",C19)),TRIM(LEFT(C19,FIND(" | ",C19)-1)),C19))
A20: =IF(C20="","",9) | D20: =IF(C20="","",IFERROR(VLOOKUP(P20,PigmentyKlucz,4,FALSE),"BRAK W BAZIE")) | E20: =IF(C20="","",IFERROR(SUMIF(RECEPTURA_ORYGINALNA!$I$12:$I$51,P20,RECEPTURA_ORYGINALNA!$E$12:$E$51),0)) | G20: =IF(C20="","",N(F20)-N(E20)) | H20: =IF(C20="","",IF(N(E20)=0,IF(N(F20)>0,"",0),IFERROR((N(F20)-N(E20))/N(E20),0))) | I20: =IF(C20="","",IF(MasaOryg=0,"",N(E20)/MasaOryg)) | J20: =IF(C20="","",IF(MasaWlasna=0,"",N(F20)/MasaWlasna)) | K20: =IF(C20="","",IF(AND(N(E20)>0,N(F20)=0),"USUNIĘTO",IF(AND(N(E20)=0,N(F20)>0),"DODANO",IF(N(F20)>N(E20),"ZWIĘKSZONO",IF(N(F20)<N(E20),"ZMNIEJSZONO","BEZ ZMIAN"))))) | M20: =IF(C20="","",IFERROR(N(F20)*MasaDocelowa/MasaWlasna,0)) | N20: =IF(C20="","",IF(COUNTIF($P$12:$P$51,P20)>1,"DUPLIKAT","OK")) | O20: =IF(C20="","",IF(B20="","BRAK SYSTEMU",IF(ISERROR(VLOOKUP(P20,PigmentyKlucz,1,FALSE)),"BRAK W BAZIE","OK"))) | P20: =IF(C20="","",B20&"|"&IF(ISNUMBER(FIND(" | ",C20)),TRIM(LEFT(C20,FIND(" | ",C20)-1)),C20))
A21: =IF(C21="","",10) | D21: =IF(C21="","",IFERROR(VLOOKUP(P21,PigmentyKlucz,4,FALSE),"BRAK W BAZIE")) | E21: =IF(C21="","",IFERROR(SUMIF(RECEPTURA_ORYGINALNA!$I$12:$I$51,P21,RECEPTURA_ORYGINALNA!$E$12:$E$51),0)) | G21: =IF(C21="","",N(F21)-N(E21)) | H21: =IF(C21="","",IF(N(E21)=0,IF(N(F21)>0,"",0),IFERROR((N(F21)-N(E21))/N(E21),0))) | I21: =IF(C21="","",IF(MasaOryg=0,"",N(E21)/MasaOryg)) | J21: =IF(C21="","",IF(MasaWlasna=0,"",N(F21)/MasaWlasna)) | K21: =IF(C21="","",IF(AND(N(E21)>0,N(F21)=0),"USUNIĘTO",IF(AND(N(E21)=0,N(F21)>0),"DODANO",IF(N(F21)>N(E21),"ZWIĘKSZONO",IF(N(F21)<N(E21),"ZMNIEJSZONO","BEZ ZMIAN"))))) | M21: =IF(C21="","",IFERROR(N(F21)*MasaDocelowa/MasaWlasna,0)) | N21: =IF(C21="","",IF(COUNTIF($P$12:$P$51,P21)>1,"DUPLIKAT","OK")) | O21: =IF(C21="","",IF(B21="","BRAK SYSTEMU",IF(ISERROR(VLOOKUP(P21,PigmentyKlucz,1,FALSE)),"BRAK W BAZIE","OK"))) | P21: =IF(C21="","",B21&"|"&IF(ISNUMBER(FIND(" | ",C21)),TRIM(LEFT(C21,FIND(" | ",C21)-1)),C21))
A22: =IF(C22="","",11) | D22: =IF(C22="","",IFERROR(VLOOKUP(P22,PigmentyKlucz,4,FALSE),"BRAK W BAZIE")) | E22: =IF(C22="","",IFERROR(SUMIF(RECEPTURA_ORYGINALNA!$I$12:$I$51,P22,RECEPTURA_ORYGINALNA!$E$12:$E$51),0)) | G22: =IF(C22="","",N(F22)-N(E22)) | H22: =IF(C22="","",IF(N(E22)=0,IF(N(F22)>0,"",0),IFERROR((N(F22)-N(E22))/N(E22),0))) | I22: =IF(C22="","",IF(MasaOryg=0,"",N(E22)/MasaOryg)) | J22: =IF(C22="","",IF(MasaWlasna=0,"",N(F22)/MasaWlasna)) | K22: =IF(C22="","",IF(AND(N(E22)>0,N(F22)=0),"USUNIĘTO",IF(AND(N(E22)=0,N(F22)>0),"DODANO",IF(N(F22)>N(E22),"ZWIĘKSZONO",IF(N(F22)<N(E22),"ZMNIEJSZONO","BEZ ZMIAN"))))) | M22: =IF(C22="","",IFERROR(N(F22)*MasaDocelowa/MasaWlasna,0)) | N22: =IF(C22="","",IF(COUNTIF($P$12:$P$51,P22)>1,"DUPLIKAT","OK")) | O22: =IF(C22="","",IF(B22="","BRAK SYSTEMU",IF(ISERROR(VLOOKUP(P22,PigmentyKlucz,1,FALSE)),"BRAK W BAZIE","OK"))) | P22: =IF(C22="","",B22&"|"&IF(ISNUMBER(FIND(" | ",C22)),TRIM(LEFT(C22,FIND(" | ",C22)-1)),C22))
A23: =IF(C23="","",12) | D23: =IF(C23="","",IFERROR(VLOOKUP(P23,PigmentyKlucz,4,FALSE),"BRAK W BAZIE")) | E23: =IF(C23="","",IFERROR(SUMIF(RECEPTURA_ORYGINALNA!$I$12:$I$51,P23,RECEPTURA_ORYGINALNA!$E$12:$E$51),0)) | G23: =IF(C23="","",N(F23)-N(E23)) | H23: =IF(C23="","",IF(N(E23)=0,IF(N(F23)>0,"",0),IFERROR((N(F23)-N(E23))/N(E23),0))) | I23: =IF(C23="","",IF(MasaOryg=0,"",N(E23)/MasaOryg)) | J23: =IF(C23="","",IF(MasaWlasna=0,"",N(F23)/MasaWlasna)) | K23: =IF(C23="","",IF(AND(N(E23)>0,N(F23)=0),"USUNIĘTO",IF(AND(N(E23)=0,N(F23)>0),"DODANO",IF(N(F23)>N(E23),"ZWIĘKSZONO",IF(N(F23)<N(E23),"ZMNIEJSZONO","BEZ ZMIAN"))))) | M23: =IF(C23="","",IFERROR(N(F23)*MasaDocelowa/MasaWlasna,0)) | N23: =IF(C23="","",IF(COUNTIF($P$12:$P$51,P23)>1,"DUPLIKAT","OK")) | O23: =IF(C23="","",IF(B23="","BRAK SYSTEMU",IF(ISERROR(VLOOKUP(P23,PigmentyKlucz,1,FALSE)),"BRAK W BAZIE","OK"))) | P23: =IF(C23="","",B23&"|"&IF(ISNUMBER(FIND(" | ",C23)),TRIM(LEFT(C23,FIND(" | ",C23)-1)),C23))
A24: =IF(C24="","",13) | D24: =IF(C24="","",IFERROR(VLOOKUP(P24,PigmentyKlucz,4,FALSE),"BRAK W BAZIE")) | E24: =IF(C24="","",IFERROR(SUMIF(RECEPTURA_ORYGINALNA!$I$12:$I$51,P24,RECEPTURA_ORYGINALNA!$E$12:$E$51),0)) | G24: =IF(C24="","",N(F24)-N(E24)) | H24: =IF(C24="","",IF(N(E24)=0,IF(N(F24)>0,"",0),IFERROR((N(F24)-N(E24))/N(E24),0))) | I24: =IF(C24="","",IF(MasaOryg=0,"",N(E24)/MasaOryg)) | J24: =IF(C24="","",IF(MasaWlasna=0,"",N(F24)/MasaWlasna)) | K24: =IF(C24="","",IF(AND(N(E24)>0,N(F24)=0),"USUNIĘTO",IF(AND(N(E24)=0,N(F24)>0),"DODANO",IF(N(F24)>N(E24),"ZWIĘKSZONO",IF(N(F24)<N(E24),"ZMNIEJSZONO","BEZ ZMIAN"))))) | M24: =IF(C24="","",IFERROR(N(F24)*MasaDocelowa/MasaWlasna,0)) | N24: =IF(C24="","",IF(COUNTIF($P$12:$P$51,P24)>1,"DUPLIKAT","OK")) | O24: =IF(C24="","",IF(B24="","BRAK SYSTEMU",IF(ISERROR(VLOOKUP(P24,PigmentyKlucz,1,FALSE)),"BRAK W BAZIE","OK"))) | P24: =IF(C24="","",B24&"|"&IF(ISNUMBER(FIND(" | ",C24)),TRIM(LEFT(C24,FIND(" | ",C24)-1)),C24))
A25: =IF(C25="","",14) | D25: =IF(C25="","",IFERROR(VLOOKUP(P25,PigmentyKlucz,4,FALSE),"BRAK W BAZIE")) | E25: =IF(C25="","",IFERROR(SUMIF(RECEPTURA_ORYGINALNA!$I$12:$I$51,P25,RECEPTURA_ORYGINALNA!$E$12:$E$51),0)) | G25: =IF(C25="","",N(F25)-N(E25)) | H25: =IF(C25="","",IF(N(E25)=0,IF(N(F25)>0,"",0),IFERROR((N(F25)-N(E25))/N(E25),0))) | I25: =IF(C25="","",IF(MasaOryg=0,"",N(E25)/MasaOryg)) | J25: =IF(C25="","",IF(MasaWlasna=0,"",N(F25)/MasaWlasna)) | K25: =IF(C25="","",IF(AND(N(E25)>0,N(F25)=0),"USUNIĘTO",IF(AND(N(E25)=0,N(F25)>0),"DODANO",IF(N(F25)>N(E25),"ZWIĘKSZONO",IF(N(F25)<N(E25),"ZMNIEJSZONO","BEZ ZMIAN"))))) | M25: =IF(C25="","",IFERROR(N(F25)*MasaDocelowa/MasaWlasna,0)) | N25: =IF(C25="","",IF(COUNTIF($P$12:$P$51,P25)>1,"DUPLIKAT","OK")) | O25: =IF(C25="","",IF(B25="","BRAK SYSTEMU",IF(ISERROR(VLOOKUP(P25,PigmentyKlucz,1,FALSE)),"BRAK W BAZIE","OK"))) | P25: =IF(C25="","",B25&"|"&IF(ISNUMBER(FIND(" | ",C25)),TRIM(LEFT(C25,FIND(" | ",C25)-1)),C25))
A26: =IF(C26="","",15) | D26: =IF(C26="","",IFERROR(VLOOKUP(P26,PigmentyKlucz,4,FALSE),"BRAK W BAZIE")) | E26: =IF(C26="","",IFERROR(SUMIF(RECEPTURA_ORYGINALNA!$I$12:$I$51,P26,RECEPTURA_ORYGINALNA!$E$12:$E$51),0)) | G26: =IF(C26="","",N(F26)-N(E26)) | H26: =IF(C26="","",IF(N(E26)=0,IF(N(F26)>0,"",0),IFERROR((N(F26)-N(E26))/N(E26),0))) | I26: =IF(C26="","",IF(MasaOryg=0,"",N(E26)/MasaOryg)) | J26: =IF(C26="","",IF(MasaWlasna=0,"",N(F26)/MasaWlasna)) | K26: =IF(C26="","",IF(AND(N(E26)>0,N(F26)=0),"USUNIĘTO",IF(AND(N(E26)=0,N(F26)>0),"DODANO",IF(N(F26)>N(E26),"ZWIĘKSZONO",IF(N(F26)<N(E26),"ZMNIEJSZONO","BEZ ZMIAN"))))) | M26: =IF(C26="","",IFERROR(N(F26)*MasaDocelowa/MasaWlasna,0)) | N26: =IF(C26="","",IF(COUNTIF($P$12:$P$51,P26)>1,"DUPLIKAT","OK")) | O26: =IF(C26="","",IF(B26="","BRAK SYSTEMU",IF(ISERROR(VLOOKUP(P26,PigmentyKlucz,1,FALSE)),"BRAK W BAZIE","OK"))) | P26: =IF(C26="","",B26&"|"&IF(ISNUMBER(FIND(" | ",C26)),TRIM(LEFT(C26,FIND(" | ",C26)-1)),C26))
A27: =IF(C27="","",16) | D27: =IF(C27="","",IFERROR(VLOOKUP(P27,PigmentyKlucz,4,FALSE),"BRAK W BAZIE")) | E27: =IF(C27="","",IFERROR(SUMIF(RECEPTURA_ORYGINALNA!$I$12:$I$51,P27,RECEPTURA_ORYGINALNA!$E$12:$E$51),0)) | G27: =IF(C27="","",N(F27)-N(E27)) | H27: =IF(C27="","",IF(N(E27)=0,IF(N(F27)>0,"",0),IFERROR((N(F27)-N(E27))/N(E27),0))) | I27: =IF(C27="","",IF(MasaOryg=0,"",N(E27)/MasaOryg)) | J27: =IF(C27="","",IF(MasaWlasna=0,"",N(F27)/MasaWlasna)) | K27: =IF(C27="","",IF(AND(N(E27)>0,N(F27)=0),"USUNIĘTO",IF(AND(N(E27)=0,N(F27)>0),"DODANO",IF(N(F27)>N(E27),"ZWIĘKSZONO",IF(N(F27)<N(E27),"ZMNIEJSZONO","BEZ ZMIAN"))))) | M27: =IF(C27="","",IFERROR(N(F27)*MasaDocelowa/MasaWlasna,0)) | N27: =IF(C27="","",IF(COUNTIF($P$12:$P$51,P27)>1,"DUPLIKAT","OK")) | O27: =IF(C27="","",IF(B27="","BRAK SYSTEMU",IF(ISERROR(VLOOKUP(P27,PigmentyKlucz,1,FALSE)),"BRAK W BAZIE","OK"))) | P27: =IF(C27="","",B27&"|"&IF(ISNUMBER(FIND(" | ",C27)),TRIM(LEFT(C27,FIND(" | ",C27)-1)),C27))
A28: =IF(C28="","",17) | D28: =IF(C28="","",IFERROR(VLOOKUP(P28,PigmentyKlucz,4,FALSE),"BRAK W BAZIE")) | E28: =IF(C28="","",IFERROR(SUMIF(RECEPTURA_ORYGINALNA!$I$12:$I$51,P28,RECEPTURA_ORYGINALNA!$E$12:$E$51),0)) | G28: =IF(C28="","",N(F28)-N(E28)) | H28: =IF(C28="","",IF(N(E28)=0,IF(N(F28)>0,"",0),IFERROR((N(F28)-N(E28))/N(E28),0))) | I28: =IF(C28="","",IF(MasaOryg=0,"",N(E28)/MasaOryg)) | J28: =IF(C28="","",IF(MasaWlasna=0,"",N(F28)/MasaWlasna)) | K28: =IF(C28="","",IF(AND(N(E28)>0,N(F28)=0),"USUNIĘTO",IF(AND(N(E28)=0,N(F28)>0),"DODANO",IF(N(F28)>N(E28),"ZWIĘKSZONO",IF(N(F28)<N(E28),"ZMNIEJSZONO","BEZ ZMIAN"))))) | M28: =IF(C28="","",IFERROR(N(F28)*MasaDocelowa/MasaWlasna,0)) | N28: =IF(C28="","",IF(COUNTIF($P$12:$P$51,P28)>1,"DUPLIKAT","OK")) | O28: =IF(C28="","",IF(B28="","BRAK SYSTEMU",IF(ISERROR(VLOOKUP(P28,PigmentyKlucz,1,FALSE)),"BRAK W BAZIE","OK"))) | P28: =IF(C28="","",B28&"|"&IF(ISNUMBER(FIND(" | ",C28)),TRIM(LEFT(C28,FIND(" | ",C28)-1)),C28))
A29: =IF(C29="","",18) | D29: =IF(C29="","",IFERROR(VLOOKUP(P29,PigmentyKlucz,4,FALSE),"BRAK W BAZIE")) | E29: =IF(C29="","",IFERROR(SUMIF(RECEPTURA_ORYGINALNA!$I$12:$I$51,P29,RECEPTURA_ORYGINALNA!$E$12:$E$51),0)) | G29: =IF(C29="","",N(F29)-N(E29)) | H29: =IF(C29="","",IF(N(E29)=0,IF(N(F29)>0,"",0),IFERROR((N(F29)-N(E29))/N(E29),0))) | I29: =IF(C29="","",IF(MasaOryg=0,"",N(E29)/MasaOryg)) | J29: =IF(C29="","",IF(MasaWlasna=0,"",N(F29)/MasaWlasna)) | K29: =IF(C29="","",IF(AND(N(E29)>0,N(F29)=0),"USUNIĘTO",IF(AND(N(E29)=0,N(F29)>0),"DODANO",IF(N(F29)>N(E29),"ZWIĘKSZONO",IF(N(F29)<N(E29),"ZMNIEJSZONO","BEZ ZMIAN"))))) | M29: =IF(C29="","",IFERROR(N(F29)*MasaDocelowa/MasaWlasna,0)) | N29: =IF(C29="","",IF(COUNTIF($P$12:$P$51,P29)>1,"DUPLIKAT","OK")) | O29: =IF(C29="","",IF(B29="","BRAK SYSTEMU",IF(ISERROR(VLOOKUP(P29,PigmentyKlucz,1,FALSE)),"BRAK W BAZIE","OK"))) | P29: =IF(C29="","",B29&"|"&IF(ISNUMBER(FIND(" | ",C29)),TRIM(LEFT(C29,FIND(" | ",C29)-1)),C29))
A30: =IF(C30="","",19) | D30: =IF(C30="","",IFERROR(VLOOKUP(P30,PigmentyKlucz,4,FALSE),"BRAK W BAZIE")) | E30: =IF(C30="","",IFERROR(SUMIF(RECEPTURA_ORYGINALNA!$I$12:$I$51,P30,RECEPTURA_ORYGINALNA!$E$12:$E$51),0)) | G30: =IF(C30="","",N(F30)-N(E30)) | H30: =IF(C30="","",IF(N(E30)=0,IF(N(F30)>0,"",0),IFERROR((N(F30)-N(E30))/N(E30),0))) | I30: =IF(C30="","",IF(MasaOryg=0,"",N(E30)/MasaOryg)) | J30: =IF(C30="","",IF(MasaWlasna=0,"",N(F30)/MasaWlasna)) | K30: =IF(C30="","",IF(AND(N(E30)>0,N(F30)=0),"USUNIĘTO",IF(AND(N(E30)=0,N(F30)>0),"DODANO",IF(N(F30)>N(E30),"ZWIĘKSZONO",IF(N(F30)<N(E30),"ZMNIEJSZONO","BEZ ZMIAN"))))) | M30: =IF(C30="","",IFERROR(N(F30)*MasaDocelowa/MasaWlasna,0)) | N30: =IF(C30="","",IF(COUNTIF($P$12:$P$51,P30)>1,"DUPLIKAT","OK")) | O30: =IF(C30="","",IF(B30="","BRAK SYSTEMU",IF(ISERROR(VLOOKUP(P30,PigmentyKlucz,1,FALSE)),"BRAK W BAZIE","OK"))) | P30: =IF(C30="","",B30&"|"&IF(ISNUMBER(FIND(" | ",C30)),TRIM(LEFT(C30,FIND(" | ",C30)-1)),C30))
A31: =IF(C31="","",20) | D31: =IF(C31="","",IFERROR(VLOOKUP(P31,PigmentyKlucz,4,FALSE),"BRAK W BAZIE")) | E31: =IF(C31="","",IFERROR(SUMIF(RECEPTURA_ORYGINALNA!$I$12:$I$51,P31,RECEPTURA_ORYGINALNA!$E$12:$E$51),0)) | G31: =IF(C31="","",N(F31)-N(E31)) | H31: =IF(C31="","",IF(N(E31)=0,IF(N(F31)>0,"",0),IFERROR((N(F31)-N(E31))/N(E31),0))) | I31: =IF(C31="","",IF(MasaOryg=0,"",N(E31)/MasaOryg)) | J31: =IF(C31="","",IF(MasaWlasna=0,"",N(F31)/MasaWlasna)) | K31: =IF(C31="","",IF(AND(N(E31)>0,N(F31)=0),"USUNIĘTO",IF(AND(N(E31)=0,N(F31)>0),"DODANO",IF(N(F31)>N(E31),"ZWIĘKSZONO",IF(N(F31)<N(E31),"ZMNIEJSZONO","BEZ ZMIAN"))))) | M31: =IF(C31="","",IFERROR(N(F31)*MasaDocelowa/MasaWlasna,0)) | N31: =IF(C31="","",IF(COUNTIF($P$12:$P$51,P31)>1,"DUPLIKAT","OK")) | O31: =IF(C31="","",IF(B31="","BRAK SYSTEMU",IF(ISERROR(VLOOKUP(P31,PigmentyKlucz,1,FALSE)),"BRAK W BAZIE","OK"))) | P31: =IF(C31="","",B31&"|"&IF(ISNUMBER(FIND(" | ",C31)),TRIM(LEFT(C31,FIND(" | ",C31)-1)),C31))
A32: =IF(C32="","",21) | D32: =IF(C32="","",IFERROR(VLOOKUP(P32,PigmentyKlucz,4,FALSE),"BRAK W BAZIE")) | E32: =IF(C32="","",IFERROR(SUMIF(RECEPTURA_ORYGINALNA!$I$12:$I$51,P32,RECEPTURA_ORYGINALNA!$E$12:$E$51),0)) | G32: =IF(C32="","",N(F32)-N(E32)) | H32: =IF(C32="","",IF(N(E32)=0,IF(N(F32)>0,"",0),IFERROR((N(F32)-N(E32))/N(E32),0))) | I32: =IF(C32="","",IF(MasaOryg=0,"",N(E32)/MasaOryg)) | J32: =IF(C32="","",IF(MasaWlasna=0,"",N(F32)/MasaWlasna)) | K32: =IF(C32="","",IF(AND(N(E32)>0,N(F32)=0),"USUNIĘTO",IF(AND(N(E32)=0,N(F32)>0),"DODANO",IF(N(F32)>N(E32),"ZWIĘKSZONO",IF(N(F32)<N(E32),"ZMNIEJSZONO","BEZ ZMIAN"))))) | M32: =IF(C32="","",IFERROR(N(F32)*MasaDocelowa/MasaWlasna,0)) | N32: =IF(C32="","",IF(COUNTIF($P$12:$P$51,P32)>1,"DUPLIKAT","OK")) | O32: =IF(C32="","",IF(B32="","BRAK SYSTEMU",IF(ISERROR(VLOOKUP(P32,PigmentyKlucz,1,FALSE)),"BRAK W BAZIE","OK"))) | P32: =IF(C32="","",B32&"|"&IF(ISNUMBER(FIND(" | ",C32)),TRIM(LEFT(C32,FIND(" | ",C32)-1)),C32))
A33: =IF(C33="","",22) | D33: =IF(C33="","",IFERROR(VLOOKUP(P33,PigmentyKlucz,4,FALSE),"BRAK W BAZIE")) | E33: =IF(C33="","",IFERROR(SUMIF(RECEPTURA_ORYGINALNA!$I$12:$I$51,P33,RECEPTURA_ORYGINALNA!$E$12:$E$51),0)) | G33: =IF(C33="","",N(F33)-N(E33)) | H33: =IF(C33="","",IF(N(E33)=0,IF(N(F33)>0,"",0),IFERROR((N(F33)-N(E33))/N(E33),0))) | I33: =IF(C33="","",IF(MasaOryg=0,"",N(E33)/MasaOryg)) | J33: =IF(C33="","",IF(MasaWlasna=0,"",N(F33)/MasaWlasna)) | K33: =IF(C33="","",IF(AND(N(E33)>0,N(F33)=0),"USUNIĘTO",IF(AND(N(E33)=0,N(F33)>0),"DODANO",IF(N(F33)>N(E33),"ZWIĘKSZONO",IF(N(F33)<N(E33),"ZMNIEJSZONO","BEZ ZMIAN"))))) | M33: =IF(C33="","",IFERROR(N(F33)*MasaDocelowa/MasaWlasna,0)) | N33: =IF(C33="","",IF(COUNTIF($P$12:$P$51,P33)>1,"DUPLIKAT","OK")) | O33: =IF(C33="","",IF(B33="","BRAK SYSTEMU",IF(ISERROR(VLOOKUP(P33,PigmentyKlucz,1,FALSE)),"BRAK W BAZIE","OK"))) | P33: =IF(C33="","",B33&"|"&IF(ISNUMBER(FIND(" | ",C33)),TRIM(LEFT(C33,FIND(" | ",C33)-1)),C33))
A34: =IF(C34="","",23) | D34: =IF(C34="","",IFERROR(VLOOKUP(P34,PigmentyKlucz,4,FALSE),"BRAK W BAZIE")) | E34: =IF(C34="","",IFERROR(SUMIF(RECEPTURA_ORYGINALNA!$I$12:$I$51,P34,RECEPTURA_ORYGINALNA!$E$12:$E$51),0)) | G34: =IF(C34="","",N(F34)-N(E34)) | H34: =IF(C34="","",IF(N(E34)=0,IF(N(F34)>0,"",0),IFERROR((N(F34)-N(E34))/N(E34),0))) | I34: =IF(C34="","",IF(MasaOryg=0,"",N(E34)/MasaOryg)) | J34: =IF(C34="","",IF(MasaWlasna=0,"",N(F34)/MasaWlasna)) | K34: =IF(C34="","",IF(AND(N(E34)>0,N(F34)=0),"USUNIĘTO",IF(AND(N(E34)=0,N(F34)>0),"DODANO",IF(N(F34)>N(E34),"ZWIĘKSZONO",IF(N(F34)<N(E34),"ZMNIEJSZONO","BEZ ZMIAN"))))) | M34: =IF(C34="","",IFERROR(N(F34)*MasaDocelowa/MasaWlasna,0)) | N34: =IF(C34="","",IF(COUNTIF($P$12:$P$51,P34)>1,"DUPLIKAT","OK")) | O34: =IF(C34="","",IF(B34="","BRAK SYSTEMU",IF(ISERROR(VLOOKUP(P34,PigmentyKlucz,1,FALSE)),"BRAK W BAZIE","OK"))) | P34: =IF(C34="","",B34&"|"&IF(ISNUMBER(FIND(" | ",C34)),TRIM(LEFT(C34,FIND(" | ",C34)-1)),C34))
A35: =IF(C35="","",24) | D35: =IF(C35="","",IFERROR(VLOOKUP(P35,PigmentyKlucz,4,FALSE),"BRAK W BAZIE")) | E35: =IF(C35="","",IFERROR(SUMIF(RECEPTURA_ORYGINALNA!$I$12:$I$51,P35,RECEPTURA_ORYGINALNA!$E$12:$E$51),0)) | G35: =IF(C35="","",N(F35)-N(E35)) | H35: =IF(C35="","",IF(N(E35)=0,IF(N(F35)>0,"",0),IFERROR((N(F35)-N(E35))/N(E35),0))) | I35: =IF(C35="","",IF(MasaOryg=0,"",N(E35)/MasaOryg)) | J35: =IF(C35="","",IF(MasaWlasna=0,"",N(F35)/MasaWlasna)) | K35: =IF(C35="","",IF(AND(N(E35)>0,N(F35)=0),"USUNIĘTO",IF(AND(N(E35)=0,N(F35)>0),"DODANO",IF(N(F35)>N(E35),"ZWIĘKSZONO",IF(N(F35)<N(E35),"ZMNIEJSZONO","BEZ ZMIAN"))))) | M35: =IF(C35="","",IFERROR(N(F35)*MasaDocelowa/MasaWlasna,0)) | N35: =IF(C35="","",IF(COUNTIF($P$12:$P$51,P35)>1,"DUPLIKAT","OK")) | O35: =IF(C35="","",IF(B35="","BRAK SYSTEMU",IF(ISERROR(VLOOKUP(P35,PigmentyKlucz,1,FALSE)),"BRAK W BAZIE","OK"))) | P35: =IF(C35="","",B35&"|"&IF(ISNUMBER(FIND(" | ",C35)),TRIM(LEFT(C35,FIND(" | ",C35)-1)),C35))
A36: =IF(C36="","",25) | D36: =IF(C36="","",IFERROR(VLOOKUP(P36,PigmentyKlucz,4,FALSE),"BRAK W BAZIE")) | E36: =IF(C36="","",IFERROR(SUMIF(RECEPTURA_ORYGINALNA!$I$12:$I$51,P36,RECEPTURA_ORYGINALNA!$E$12:$E$51),0)) | G36: =IF(C36="","",N(F36)-N(E36)) | H36: =IF(C36="","",IF(N(E36)=0,IF(N(F36)>0,"",0),IFERROR((N(F36)-N(E36))/N(E36),0))) | I36: =IF(C36="","",IF(MasaOryg=0,"",N(E36)/MasaOryg)) | J36: =IF(C36="","",IF(MasaWlasna=0,"",N(F36)/MasaWlasna)) | K36: =IF(C36="","",IF(AND(N(E36)>0,N(F36)=0),"USUNIĘTO",IF(AND(N(E36)=0,N(F36)>0),"DODANO",IF(N(F36)>N(E36),"ZWIĘKSZONO",IF(N(F36)<N(E36),"ZMNIEJSZONO","BEZ ZMIAN"))))) | M36: =IF(C36="","",IFERROR(N(F36)*MasaDocelowa/MasaWlasna,0)) | N36: =IF(C36="","",IF(COUNTIF($P$12:$P$51,P36)>1,"DUPLIKAT","OK")) | O36: =IF(C36="","",IF(B36="","BRAK SYSTEMU",IF(ISERROR(VLOOKUP(P36,PigmentyKlucz,1,FALSE)),"BRAK W BAZIE","OK"))) | P36: =IF(C36="","",B36&"|"&IF(ISNUMBER(FIND(" | ",C36)),TRIM(LEFT(C36,FIND(" | ",C36)-1)),C36))
A37: =IF(C37="","",26) | D37: =IF(C37="","",IFERROR(VLOOKUP(P37,PigmentyKlucz,4,FALSE),"BRAK W BAZIE")) | E37: =IF(C37="","",IFERROR(SUMIF(RECEPTURA_ORYGINALNA!$I$12:$I$51,P37,RECEPTURA_ORYGINALNA!$E$12:$E$51),0)) | G37: =IF(C37="","",N(F37)-N(E37)) | H37: =IF(C37="","",IF(N(E37)=0,IF(N(F37)>0,"",0),IFERROR((N(F37)-N(E37))/N(E37),0))) | I37: =IF(C37="","",IF(MasaOryg=0,"",N(E37)/MasaOryg)) | J37: =IF(C37="","",IF(MasaWlasna=0,"",N(F37)/MasaWlasna)) | K37: =IF(C37="","",IF(AND(N(E37)>0,N(F37)=0),"USUNIĘTO",IF(AND(N(E37)=0,N(F37)>0),"DODANO",IF(N(F37)>N(E37),"ZWIĘKSZONO",IF(N(F37)<N(E37),"ZMNIEJSZONO","BEZ ZMIAN"))))) | M37: =IF(C37="","",IFERROR(N(F37)*MasaDocelowa/MasaWlasna,0)) | N37: =IF(C37="","",IF(COUNTIF($P$12:$P$51,P37)>1,"DUPLIKAT","OK")) | O37: =IF(C37="","",IF(B37="","BRAK SYSTEMU",IF(ISERROR(VLOOKUP(P37,PigmentyKlucz,1,FALSE)),"BRAK W BAZIE","OK"))) | P37: =IF(C37="","",B37&"|"&IF(ISNUMBER(FIND(" | ",C37)),TRIM(LEFT(C37,FIND(" | ",C37)-1)),C37))
A38: =IF(C38="","",27) | D38: =IF(C38="","",IFERROR(VLOOKUP(P38,PigmentyKlucz,4,FALSE),"BRAK W BAZIE")) | E38: =IF(C38="","",IFERROR(SUMIF(RECEPTURA_ORYGINALNA!$I$12:$I$51,P38,RECEPTURA_ORYGINALNA!$E$12:$E$51),0)) | G38: =IF(C38="","",N(F38)-N(E38)) | H38: =IF(C38="","",IF(N(E38)=0,IF(N(F38)>0,"",0),IFERROR((N(F38)-N(E38))/N(E38),0))) | I38: =IF(C38="","",IF(MasaOryg=0,"",N(E38)/MasaOryg)) | J38: =IF(C38="","",IF(MasaWlasna=0,"",N(F38)/MasaWlasna)) | K38: =IF(C38="","",IF(AND(N(E38)>0,N(F38)=0),"USUNIĘTO",IF(AND(N(E38)=0,N(F38)>0),"DODANO",IF(N(F38)>N(E38),"ZWIĘKSZONO",IF(N(F38)<N(E38),"ZMNIEJSZONO","BEZ ZMIAN"))))) | M38: =IF(C38="","",IFERROR(N(F38)*MasaDocelowa/MasaWlasna,0)) | N38: =IF(C38="","",IF(COUNTIF($P$12:$P$51,P38)>1,"DUPLIKAT","OK")) | O38: =IF(C38="","",IF(B38="","BRAK SYSTEMU",IF(ISERROR(VLOOKUP(P38,PigmentyKlucz,1,FALSE)),"BRAK W BAZIE","OK"))) | P38: =IF(C38="","",B38&"|"&IF(ISNUMBER(FIND(" | ",C38)),TRIM(LEFT(C38,FIND(" | ",C38)-1)),C38))
A39: =IF(C39="","",28) | D39: =IF(C39="","",IFERROR(VLOOKUP(P39,PigmentyKlucz,4,FALSE),"BRAK W BAZIE")) | E39: =IF(C39="","",IFERROR(SUMIF(RECEPTURA_ORYGINALNA!$I$12:$I$51,P39,RECEPTURA_ORYGINALNA!$E$12:$E$51),0)) | G39: =IF(C39="","",N(F39)-N(E39)) | H39: =IF(C39="","",IF(N(E39)=0,IF(N(F39)>0,"",0),IFERROR((N(F39)-N(E39))/N(E39),0))) | I39: =IF(C39="","",IF(MasaOryg=0,"",N(E39)/MasaOryg)) | J39: =IF(C39="","",IF(MasaWlasna=0,"",N(F39)/MasaWlasna)) | K39: =IF(C39="","",IF(AND(N(E39)>0,N(F39)=0),"USUNIĘTO",IF(AND(N(E39)=0,N(F39)>0),"DODANO",IF(N(F39)>N(E39),"ZWIĘKSZONO",IF(N(F39)<N(E39),"ZMNIEJSZONO","BEZ ZMIAN"))))) | M39: =IF(C39="","",IFERROR(N(F39)*MasaDocelowa/MasaWlasna,0)) | N39: =IF(C39="","",IF(COUNTIF($P$12:$P$51,P39)>1,"DUPLIKAT","OK")) | O39: =IF(C39="","",IF(B39="","BRAK SYSTEMU",IF(ISERROR(VLOOKUP(P39,PigmentyKlucz,1,FALSE)),"BRAK W BAZIE","OK"))) | P39: =IF(C39="","",B39&"|"&IF(ISNUMBER(FIND(" | ",C39)),TRIM(LEFT(C39,FIND(" | ",C39)-1)),C39))
A40: =IF(C40="","",29) | D40: =IF(C40="","",IFERROR(VLOOKUP(P40,PigmentyKlucz,4,FALSE),"BRAK W BAZIE")) | E40: =IF(C40="","",IFERROR(SUMIF(RECEPTURA_ORYGINALNA!$I$12:$I$51,P40,RECEPTURA_ORYGINALNA!$E$12:$E$51),0)) | G40: =IF(C40="","",N(F40)-N(E40)) | H40: =IF(C40="","",IF(N(E40)=0,IF(N(F40)>0,"",0),IFERROR((N(F40)-N(E40))/N(E40),0))) | I40: =IF(C40="","",IF(MasaOryg=0,"",N(E40)/MasaOryg)) | J40: =IF(C40="","",IF(MasaWlasna=0,"",N(F40)/MasaWlasna)) | K40: =IF(C40="","",IF(AND(N(E40)>0,N(F40)=0),"USUNIĘTO",IF(AND(N(E40)=0,N(F40)>0),"DODANO",IF(N(F40)>N(E40),"ZWIĘKSZONO",IF(N(F40)<N(E40),"ZMNIEJSZONO","BEZ ZMIAN"))))) | M40: =IF(C40="","",IFERROR(N(F40)*MasaDocelowa/MasaWlasna,0)) | N40: =IF(C40="","",IF(COUNTIF($P$12:$P$51,P40)>1,"DUPLIKAT","OK")) | O40: =IF(C40="","",IF(B40="","BRAK SYSTEMU",IF(ISERROR(VLOOKUP(P40,PigmentyKlucz,1,FALSE)),"BRAK W BAZIE","OK"))) | P40: =IF(C40="","",B40&"|"&IF(ISNUMBER(FIND(" | ",C40)),TRIM(LEFT(C40,FIND(" | ",C40)-1)),C40))
A41: =IF(C41="","",30) | D41: =IF(C41="","",IFERROR(VLOOKUP(P41,PigmentyKlucz,4,FALSE),"BRAK W BAZIE")) | E41: =IF(C41="","",IFERROR(SUMIF(RECEPTURA_ORYGINALNA!$I$12:$I$51,P41,RECEPTURA_ORYGINALNA!$E$12:$E$51),0)) | G41: =IF(C41="","",N(F41)-N(E41)) | H41: =IF(C41="","",IF(N(E41)=0,IF(N(F41)>0,"",0),IFERROR((N(F41)-N(E41))/N(E41),0))) | I41: =IF(C41="","",IF(MasaOryg=0,"",N(E41)/MasaOryg)) | J41: =IF(C41="","",IF(MasaWlasna=0,"",N(F41)/MasaWlasna)) | K41: =IF(C41="","",IF(AND(N(E41)>0,N(F41)=0),"USUNIĘTO",IF(AND(N(E41)=0,N(F41)>0),"DODANO",IF(N(F41)>N(E41),"ZWIĘKSZONO",IF(N(F41)<N(E41),"ZMNIEJSZONO","BEZ ZMIAN"))))) | M41: =IF(C41="","",IFERROR(N(F41)*MasaDocelowa/MasaWlasna,0)) | N41: =IF(C41="","",IF(COUNTIF($P$12:$P$51,P41)>1,"DUPLIKAT","OK")) | O41: =IF(C41="","",IF(B41="","BRAK SYSTEMU",IF(ISERROR(VLOOKUP(P41,PigmentyKlucz,1,FALSE)),"BRAK W BAZIE","OK"))) | P41: =IF(C41="","",B41&"|"&IF(ISNUMBER(FIND(" | ",C41)),TRIM(LEFT(C41,FIND(" | ",C41)-1)),C41))
A42: =IF(C42="","",31) | D42: =IF(C42="","",IFERROR(VLOOKUP(P42,PigmentyKlucz,4,FALSE),"BRAK W BAZIE")) | E42: =IF(C42="","",IFERROR(SUMIF(RECEPTURA_ORYGINALNA!$I$12:$I$51,P42,RECEPTURA_ORYGINALNA!$E$12:$E$51),0)) | G42: =IF(C42="","",N(F42)-N(E42)) | H42: =IF(C42="","",IF(N(E42)=0,IF(N(F42)>0,"",0),IFERROR((N(F42)-N(E42))/N(E42),0))) | I42: =IF(C42="","",IF(MasaOryg=0,"",N(E42)/MasaOryg)) | J42: =IF(C42="","",IF(MasaWlasna=0,"",N(F42)/MasaWlasna)) | K42: =IF(C42="","",IF(AND(N(E42)>0,N(F42)=0),"USUNIĘTO",IF(AND(N(E42)=0,N(F42)>0),"DODANO",IF(N(F42)>N(E42),"ZWIĘKSZONO",IF(N(F42)<N(E42),"ZMNIEJSZONO","BEZ ZMIAN"))))) | M42: =IF(C42="","",IFERROR(N(F42)*MasaDocelowa/MasaWlasna,0)) | N42: =IF(C42="","",IF(COUNTIF($P$12:$P$51,P42)>1,"DUPLIKAT","OK")) | O42: =IF(C42="","",IF(B42="","BRAK SYSTEMU",IF(ISERROR(VLOOKUP(P42,PigmentyKlucz,1,FALSE)),"BRAK W BAZIE","OK"))) | P42: =IF(C42="","",B42&"|"&IF(ISNUMBER(FIND(" | ",C42)),TRIM(LEFT(C42,FIND(" | ",C42)-1)),C42))
A43: =IF(C43="","",32) | D43: =IF(C43="","",IFERROR(VLOOKUP(P43,PigmentyKlucz,4,FALSE),"BRAK W BAZIE")) | E43: =IF(C43="","",IFERROR(SUMIF(RECEPTURA_ORYGINALNA!$I$12:$I$51,P43,RECEPTURA_ORYGINALNA!$E$12:$E$51),0)) | G43: =IF(C43="","",N(F43)-N(E43)) | H43: =IF(C43="","",IF(N(E43)=0,IF(N(F43)>0,"",0),IFERROR((N(F43)-N(E43))/N(E43),0))) | I43: =IF(C43="","",IF(MasaOryg=0,"",N(E43)/MasaOryg)) | J43: =IF(C43="","",IF(MasaWlasna=0,"",N(F43)/MasaWlasna)) | K43: =IF(C43="","",IF(AND(N(E43)>0,N(F43)=0),"USUNIĘTO",IF(AND(N(E43)=0,N(F43)>0),"DODANO",IF(N(F43)>N(E43),"ZWIĘKSZONO",IF(N(F43)<N(E43),"ZMNIEJSZONO","BEZ ZMIAN"))))) | M43: =IF(C43="","",IFERROR(N(F43)*MasaDocelowa/MasaWlasna,0)) | N43: =IF(C43="","",IF(COUNTIF($P$12:$P$51,P43)>1,"DUPLIKAT","OK")) | O43: =IF(C43="","",IF(B43="","BRAK SYSTEMU",IF(ISERROR(VLOOKUP(P43,PigmentyKlucz,1,FALSE)),"BRAK W BAZIE","OK"))) | P43: =IF(C43="","",B43&"|"&IF(ISNUMBER(FIND(" | ",C43)),TRIM(LEFT(C43,FIND(" | ",C43)-1)),C43))
A44: =IF(C44="","",33) | D44: =IF(C44="","",IFERROR(VLOOKUP(P44,PigmentyKlucz,4,FALSE),"BRAK W BAZIE")) | E44: =IF(C44="","",IFERROR(SUMIF(RECEPTURA_ORYGINALNA!$I$12:$I$51,P44,RECEPTURA_ORYGINALNA!$E$12:$E$51),0)) | G44: =IF(C44="","",N(F44)-N(E44)) | H44: =IF(C44="","",IF(N(E44)=0,IF(N(F44)>0,"",0),IFERROR((N(F44)-N(E44))/N(E44),0))) | I44: =IF(C44="","",IF(MasaOryg=0,"",N(E44)/MasaOryg)) | J44: =IF(C44="","",IF(MasaWlasna=0,"",N(F44)/MasaWlasna)) | K44: =IF(C44="","",IF(AND(N(E44)>0,N(F44)=0),"USUNIĘTO",IF(AND(N(E44)=0,N(F44)>0),"DODANO",IF(N(F44)>N(E44),"ZWIĘKSZONO",IF(N(F44)<N(E44),"ZMNIEJSZONO","BEZ ZMIAN"))))) | M44: =IF(C44="","",IFERROR(N(F44)*MasaDocelowa/MasaWlasna,0)) | N44: =IF(C44="","",IF(COUNTIF($P$12:$P$51,P44)>1,"DUPLIKAT","OK")) | O44: =IF(C44="","",IF(B44="","BRAK SYSTEMU",IF(ISERROR(VLOOKUP(P44,PigmentyKlucz,1,FALSE)),"BRAK W BAZIE","OK"))) | P44: =IF(C44="","",B44&"|"&IF(ISNUMBER(FIND(" | ",C44)),TRIM(LEFT(C44,FIND(" | ",C44)-1)),C44))
...

Sheet ANALIZA
A1: ANALIZA ZMIAN
A2: KPI i wykresy odświeżają się po przeliczeniu formuł (F9 / LibreOffice: Dane → Przelicz).
A3: Nazwa | C3: =Meta_Nazwa | E3: Numer | F3: =Meta_Numer | H3: System | I3: =Meta_System
A4: Wersja | C4: =Meta_Wersja | E4: Data | F4: =Meta_Data | H4: Status % | I4: =StatusUdzialow
A6: Wskaźniki
A7: Masa oryginalna (g) | B7: =MasaOryg
A8: Masa własna (g) | B8: =MasaWlasna
A9: Różnica masy (g) | B9: =MasaWlasna-MasaOryg
A10: Liczba pigmentów (własna) | B10: =COUNTIF(RECEPTURA_WLASNA!C12:C51,"<>")
A11: Dodane | B11: =COUNTIF(RECEPTURA_WLASNA!K12:K51,"DODANO")
A12: Usunięte | B12: =COUNTIF(RECEPTURA_WLASNA!K12:K51,"USUNIĘTO")
A13: Zwiększone | B13: =COUNTIF(RECEPTURA_WLASNA!K12:K51,"ZWIĘKSZONO")
A14: Zmniejszone | B14: =COUNTIF(RECEPTURA_WLASNA!K12:K51,"ZMNIEJSZONO")
A15: Bez zmian | B15: =COUNTIF(RECEPTURA_WLASNA!K12:K51,"BEZ ZMIAN")
A16: Największa zmiana % | B16: =IFERROR(MAX(DANE_WYKRESOW!G9:G48),0)
A17: Suma % własna | B17: =IFERROR(SUM(RECEPTURA_WLASNA!J12:J51),0)
A18: Suma % oryginał | B18: =IFERROR(SUM(RECEPTURA_ORYGINALNA!G12:G51),0)

Sheet RAPORT
A1: RAPORT RECEPTURY
A2: Arkusz do wydruku. Ustawienia: A4, poziomo, dopasuj do szerokości.
A4: INFORMACJE
A5: Nazwa | B5: =Meta_Nazwa | C5: Kod koloru | D5: =Meta_Kod | E5: System bazowy | F5: =Meta_System
A6: Numer | B6: =Meta_Numer | C6: Wersja | D6: =Meta_Wersja | E6: Data | F6: =Meta_Data
A7: Producent | B7: =Meta_Producent | C7: Autor | D7: =Meta_Autor | E7: Masa docelowa (g) | F7: =MasaDocelowa
A8: Uwagi | B8: =Meta_Uwagi
A10: SKŁAD (RECEPTURA WŁASNA — ILOŚĆ DO ZWAŻENIA)
A11: LP | B11: SYSTEM | C11: PIGMENT | D11: NAZWA | E11: ILOŚĆ (g) | F11: % | G11: STATUS | H11: JEDN.
A12: =IF(RECEPTURA_WLASNA!C12="","",RECEPTURA_WLASNA!A12) | B12: =IF(RECEPTURA_WLASNA!C12="","",RECEPTURA_WLASNA!B12) | C12: =IF(RECEPTURA_WLASNA!C12="","",RECEPTURA_WLASNA!C12) | D12: =IF(RECEPTURA_WLASNA!C12="","",RECEPTURA_WLASNA!D12) | E12: =IF(RECEPTURA_WLASNA!C12="","",RECEPTURA_WLASNA!M12) | F12: =IF(RECEPTURA_WLASNA!C12="","",RECEPTURA_WLASNA!J12) | G12: =IF(RECEPTURA_WLASNA!C12="","",RECEPTURA_WLASNA!K12) | H12: =IF(RECEPTURA_WLASNA!C12="","",Ust_Jednostka)
A13: =IF(RECEPTURA_WLASNA!C13="","",RECEPTURA_WLASNA!A13) | B13: =IF(RECEPTURA_WLASNA!C13="","",RECEPTURA_WLASNA!B13) | C13: =IF(RECEPTURA_WLASNA!C13="","",RECEPTURA_WLASNA!C13) | D13: =IF(RECEPTURA_WLASNA!C13="","",RECEPTURA_WLASNA!D13) | E13: =IF(RECEPTURA_WLASNA!C13="","",RECEPTURA_WLASNA!M13) | F13: =IF(RECEPTURA_WLASNA!C13="","",RECEPTURA_WLASNA!J13) | G13: =IF(RECEPTURA_WLASNA!C13="","",RECEPTURA_WLASNA!K13) | H13: =IF(RECEPTURA_WLASNA!C13="","",Ust_Jednostka)
A14: =IF(RECEPTURA_WLASNA!C14="","",RECEPTURA_WLASNA!A14) | B14: =IF(RECEPTURA_WLASNA!C14="","",RECEPTURA_WLASNA!B14) | C14: =IF(RECEPTURA_WLASNA!C14="","",RECEPTURA_WLASNA!C14) | D14: =IF(RECEPTURA_WLASNA!C14="","",RECEPTURA_WLASNA!D14) | E14: =IF(RECEPTURA_WLASNA!C14="","",RECEPTURA_WLASNA!M14) | F14: =IF(RECEPTURA_WLASNA!C14="","",RECEPTURA_WLASNA!J14) | G14: =IF(RECEPTURA_WLASNA!C14="","",RECEPTURA_WLASNA!K14) | H14: =IF(RECEPTURA_WLASNA!C14="","",Ust_Jednostka)
A15: =IF(RECEPTURA_WLASNA!C15="","",RECEPTURA_WLASNA!A15) | B15: =IF(RECEPTURA_WLASNA!C15="","",RECEPTURA_WLASNA!B15) | C15: =IF(RECEPTURA_WLASNA!C15="","",RECEPTURA_WLASNA!C15) | D15: =IF(RECEPTURA_WLASNA!C15="","",RECEPTURA_WLASNA!D15) | E15: =IF(RECEPTURA_WLASNA!C15="","",RECEPTURA_WLASNA!M15) | F15: =IF(RECEPTURA_WLASNA!C15="","",RECEPTURA_WLASNA!J15) | G15: =IF(RECEPTURA_WLASNA!C15="","",RECEPTURA_WLASNA!K15) | H15: =IF(RECEPTURA_WLASNA!C15="","",Ust_Jednostka)
A16: =IF(RECEPTURA_WLASNA!C16="","",RECEPTURA_WLASNA!A16) | B16: =IF(RECEPTURA_WLASNA!C16="","",RECEPTURA_WLASNA!B16) | C16: =IF(RECEPTURA_WLASNA!C16="","",RECEPTURA_WLASNA!C16) | D16: =IF(RECEPTURA_WLASNA!C16="","",RECEPTURA_WLASNA!D16) | E16: =IF(RECEPTURA_WLASNA!C16="","",RECEPTURA_WLASNA!M16) | F16: =IF(RECEPTURA_WLASNA!C16="","",RECEPTURA_WLASNA!J16) | G16: =IF(RECEPTURA_WLASNA!C16="","",RECEPTURA_WLASNA!K16) | H16: =IF(RECEPTURA_WLASNA!C16="","",Ust_Jednostka)
A17: =IF(RECEPTURA_WLASNA!C17="","",RECEPTURA_WLASNA!A17) | B17: =IF(RECEPTURA_WLASNA!C17="","",RECEPTURA_WLASNA!B17) | C17: =IF(RECEPTURA_WLASNA!C17="","",RECEPTURA_WLASNA!C17) | D17: =IF(RECEPTURA_WLASNA!C17="","",RECEPTURA_WLASNA!D17) | E17: =IF(RECEPTURA_WLASNA!C17="","",RECEPTURA_WLASNA!M17) | F17: =IF(RECEPTURA_WLASNA!C17="","",RECEPTURA_WLASNA!J17) | G17: =IF(RECEPTURA_WLASNA!C17="","",RECEPTURA_WLASNA!K17) | H17: =IF(RECEPTURA_WLASNA!C17="","",Ust_Jednostka)
A18: =IF(RECEPTURA_WLASNA!C18="","",RECEPTURA_WLASNA!A18) | B18: =IF(RECEPTURA_WLASNA!C18="","",RECEPTURA_WLASNA!B18) | C18: =IF(RECEPTURA_WLASNA!C18="","",RECEPTURA_WLASNA!C18) | D18: =IF(RECEPTURA_WLASNA!C18="","",RECEPTURA_WLASNA!D18) | E18: =IF(RECEPTURA_WLASNA!C18="","",RECEPTURA_WLASNA!M18) | F18: =IF(RECEPTURA_WLASNA!C18="","",RECEPTURA_WLASNA!J18) | G18: =IF(RECEPTURA_WLASNA!C18="","",RECEPTURA_WLASNA!K18) | H18: =IF(RECEPTURA_WLASNA!C18="","",Ust_Jednostka)
A19: =IF(RECEPTURA_WLASNA!C19="","",RECEPTURA_WLASNA!A19) | B19: =IF(RECEPTURA_WLASNA!C19="","",RECEPTURA_WLASNA!B19) | C19: =IF(RECEPTURA_WLASNA!C19="","",RECEPTURA_WLASNA!C19) | D19: =IF(RECEPTURA_WLASNA!C19="","",RECEPTURA_WLASNA!D19) | E19: =IF(RECEPTURA_WLASNA!C19="","",RECEPTURA_WLASNA!M19) | F19: =IF(RECEPTURA_WLASNA!C19="","",RECEPTURA_WLASNA!J19) | G19: =IF(RECEPTURA_WLASNA!C19="","",RECEPTURA_WLASNA!K19) | H19: =IF(RECEPTURA_WLASNA!C19="","",Ust_Jednostka)
A20: =IF(RECEPTURA_WLASNA!C20="","",RECEPTURA_WLASNA!A20) | B20: =IF(RECEPTURA_WLASNA!C20="","",RECEPTURA_WLASNA!B20) | C20: =IF(RECEPTURA_WLASNA!C20="","",RECEPTURA_WLASNA!C20) | D20: =IF(RECEPTURA_WLASNA!C20="","",RECEPTURA_WLASNA!D20) | E20: =IF(RECEPTURA_WLASNA!C20="","",RECEPTURA_WLASNA!M20) | F20: =IF(RECEPTURA_WLASNA!C20="","",RECEPTURA_WLASNA!J20) | G20: =IF(RECEPTURA_WLASNA!C20="","",RECEPTURA_WLASNA!K20) | H20: =IF(RECEPTURA_WLASNA!C20="","",Ust_Jednostka)
A21: =IF(RECEPTURA_WLASNA!C21="","",RECEPTURA_WLASNA!A21) | B21: =IF(RECEPTURA_WLASNA!C21="","",RECEPTURA_WLASNA!B21) | C21: =IF(RECEPTURA_WLASNA!C21="","",RECEPTURA_WLASNA!C21) | D21: =IF(RECEPTURA_WLASNA!C21="","",RECEPTURA_WLASNA!D21) | E21: =IF(RECEPTURA_WLASNA!C21="","",RECEPTURA_WLASNA!M21) | F21: =IF(RECEPTURA_WLASNA!C21="","",RECEPTURA_WLASNA!J21) | G21: =IF(RECEPTURA_WLASNA!C21="","",RECEPTURA_WLASNA!K21) | H21: =IF(RECEPTURA_WLASNA!C21="","",Ust_Jednostka)
